Workbook

Sheet Portfolio Emissions
B1: Portfolio Emissions
B3: Partner Name:
B5: GHG emissions reduction goal (%) | F5: Data reporting period (calendar or fiscal year)
B6: Base Year | F6: Reporting toward a market-based or location-based goal?
B7: Goal End Date | F7: Energy efficiency target
D8: =IF($D$6=0, "Select Base Year",$D$6) -> Select Base Year | E8: =IF($D$8="Select Base Year","",D8+1) | F8: =IF($D$8="Select Base Year","",E8+1) | G8: =IF($D$8="Select Base Year","",F8+1) | H8: =IF($D$8="Select Base Year","",G8+1) | I8: =IF($D$8="Select Base Year","",H8+1) | J8: =IF($D$8="Select Base Year","",I8+1) | K8: =IF($D$8="Select Base Year","",J8+1) | L8: =IF($D$8="Select Base Year","",K8+1) | ... Q8: =IF($D$8="Select Base Year","",P8+1)
B10: Section 1: Portfolio Information
B12: Square Feet
B13: Number of facilities
B15: Section 2: Absolute Emissions (Metric tons CO2e)
B17: Scope 1 Emissions
B18: Stationary Emissions
B19: Mobile Emissions
B20: Fugitive Emissions
B21: Process Emissions
B22: Scope 2 Emissions (Location-Based) from Electricity & District Energy
B23: Scope 2 Emissions (Market-Based) from Electricity & District Energy
B24: Scope 3 Emissions (Location-Based) from Leased Assets (if applicable, see notes)
B25: Scope 3 Emissions (Market-Based) from Leased Assets (if applicable, see notes)
B26: Total Emissions (Metric Tons) | D26: =IFERROR(IF($J$6="Market-Based GHG Goal",SUM(D17,D23,D25),SUM(D17,D22,D24)), "") -> 0 | E26: =IFERROR(IF($J$6="Market-Based GHG Goal",SUM(E17,E23,E25),SUM(E17,E22,E24)), "") -> 0 | F26: =IFERROR(IF($J$6="Market-Based GHG Goal",SUM(F17,F23,F25),SUM(F17,F22,F24)), "") -> 0 | G26: =IFERROR(IF($J$6="Market-Based GHG Goal",SUM(G17,G23,G25),SUM(G17,G22,G24)), "") -> 0 | H26: =IFERROR(IF($J$6="Market-Based GHG Goal",SUM(H17,H23,H25),SUM(H17,H22,H24)), "") -> 0 | I26: =IFERROR(IF($J$6="Market-Based GHG Goal",SUM(I17,I23,I25),SUM(I17,I22,I24)), "") -> 0 | J26: =IFERROR(IF($J$6="Market-Based GHG Goal",SUM(J17,J23,J25),SUM(J17,J22,J24)), "") -> 0 | K26: =IFERROR(IF($J$6="Market-Based GHG Goal",SUM(K17,K23,K25),SUM(K17,K22,K24)), "") -> 0 | ... Q26: =IFERROR(IF($J$6="Market-Based GHG Goal",SUM(Q17,Q23,Q25),SUM(Q17,Q22,Q24)), "") -> 0
B27: If Applicable: Bioenergy and Biomass Emissions
B29: Section 3: GHG Emissions Reductions
B31: GHG Emissions Reductions (Metric tons CO2e) | D31: =IF(D26<>0,($D$26-D26), "") | E31: =IF(E26<>0,($D$26-E26), "") | F31: =IF(F26<>0,($D$26-F26), "") | G31: =IF(G26<>0,($D$26-G26), "") | H31: =IF(H26<>0,($D$26-H26), "") | I31: =IF(I26<>0,($D$26-I26), "") | J31: =IF(J26<>0,($D$26-J26), "") | K31: =IF(K26<>0,($D$26-K26), "") | ... Q31: =IF(Q26<>0,($D$26-Q26), "")
B32: GHG Emissions Reductions (%) | D32: =IF(D26<>0,D31/$D$26, "") | E32: =IF(E26<>0,E31/$D$26, "") | F32: =IF(F26<>0,F31/$D$26, "") | G32: =IF(G26<>0,G31/$D$26, "") | H32: =IF(H26<>0,H31/$D$26, "") | I32: =IF(I26<>0,I31/$D$26, "") | J32: =IF(J26<>0,J31/$D$26, "") | K32: =IF(K26<>0,K31/$D$26, "") | ... Q32: =IF(Q26<>0,Q31/$D$26, "")
B34: Section 4: Total Energy Use for Portfolio (Provide total Site Energy used across your organization, including facilities, vehicles, and other uses. This includes energy use associated with scope 1 and 2 emissions sources and scope 3 Leased Assets, as applicable.)
B36: Total Electricity Consumption (MWh) | D36: =IF(D38<>0, SUM(D37:D38), 0) -> 0 | E36: =IF(E38<>0, SUM(E37:E38), 0) -> 0 | F36: =IF(F38<>0, SUM(F37:F38), 0) -> 0 | G36: =IF(G38<>0, SUM(G37:G38), 0) -> 0 | H36: =IF(H38<>0, SUM(H37:H38), 0) -> 0 | I36: =IF(I38<>0, SUM(I37:I38), 0) -> 0 | J36: =IF(J38<>0, SUM(J37:J38), 0) -> 0 | K36: =IF(K38<>0, SUM(K37:K38), 0) -> 0 | ... Q36: =IF(Q38<>0, SUM(Q37:Q38), 0) -> 0
B37: Renewable Energy Generated and Used On-site (MWh)
B38: Purchased or Acquired Electricity (MWh)
B39: Physical PPAs, Competitive or Utility Products, CCAs, Self-supply (MWh)
B40: Financial / Virtual PPAs (MWh)
B41: Unbundled RECs (MWh)
B42: Remaining Grid Electricity (MWh) | D42: =D38-SUM(D39:D41) -> 0 | E42: =E38-SUM(E39:E41) -> 0 | F42: =F38-SUM(F39:F41) -> 0 | G42: =G38-SUM(G39:G41) -> 0 | H42: =H38-SUM(H39:H41) -> 0 | I42: =I38-SUM(I39:I41) -> 0 | J42: =J38-SUM(J39:J41) -> 0 | K42: =K38-SUM(K39:K41) -> 0 | ... Q42: =Q38-SUM(Q39:Q41) -> 0
B43: District Steam (MMBtu)
B44: District Hot Water (MMBtu)
B45: District Chilled Water (MMBtu)
B46: Natural Gas (MMBtu)
B47: Distillate or Light Fuel Oil (#1, 2, & 4) (MMBtu)
B48: Propane (MMBtu)
B49: Coke (MMBtu)
B50: Coal (MMBtu)
...

Sheet Facility Emissions
B1: Facility Emissions
B3: Reporting Year
B5: Facility Name or ID | C5: Gross Floor Area (Sq. Ft.) | D5: Latitude | E5: Longitude | F5: Scope 1 emissions (metric tons CO2e) | G5: Scope 2, location-based (metric tons CO2e) | H5: Scope 2, market-based (metric tons CO2e)

Sheet Comments
B1: Comments
B3: Year | C3: Description: Enter your response below

Sheet Data Validation
A1: Base year options | B1: Reporting period | I1: All Emission Factors from BEC Methodology unless otherwise noted
I2: Building Emissions Calculator Methodology (energystar.gov)
G3: Emissions Factors QC Reference Table | I3: https://www.eia.gov/environment/emissions/co2_vol_mass.php | L3: For gasoline & ethanol EF
A4: 2014 | G4: Electric Driven Chiller: 52.7 kg CO2e/MMBtu
A5: 2015 | G5: Absorption Chiller using NG: 73.86 kg CO2e/MMBtu | I5: District Steam (MMBtu) | K5: 66.4 | L5: kg CO2e/MMbtu
A6: 2016 | B6: Calendar Year (December 31) | C6: Market-Based GHG Goal | G6: Engine Driven Chiller NG: 49.29 kg CO2e/MMBtu | I6: District Hot Water (MMBtu) | K6: 66.5 | L6: kg CO2e/MMbtu
A7: 2017 | B7: January 31 | C7: Location-Based GHG Goal | G7: Fuel Oil #1: 74.21 kg CO2e/MMBtu | I7: District Chilled Water (MMBtu) | K7: =AVERAGE(52.7,73.86,49.29) -> 58.616667 | L7: kg CO2e/MMbtu
A8: 2018 | B8: February 29 | G8: Fuel Oil #2: 73.5 kg CO2e/MMBtu | I8: Natural Gas (MMBtu) | K8: 53.11 | L8: kg CO2e/MMbtu
A9: 2019 | B9: March 31 | G9: Fuel Oil #4: 75.29 kg CO2e/MMBtu | I9: Distillate or Light Fuel Oil (#1, 2, & 4) (MMBtu) | K9: =AVERAGE(74.21,73.5,75.29) -> 74.333333 | L9: kg CO2e/MMbtu
A10: 2020 | B10: April 30 | G10: Coal (anthracite): 104.44 kg CO2e/MMBtu | I10: Propane (MMBtu) | K10: 64.25 | L10: kg CO2e/MMbtu
A11: 2021 | B11: May 31 | G11: Coal (bituminous): 94.03 kg CO2e/MMBtu | I11: Coke (MMBtu) | K11: 114.42 | L11: kg CO2e/MMbtu
A12: 2022 | B12: June 30 | I12: Coal (MMBtu) | K12: =AVERAGE(104.44,94.03) -> 99.235 | L12: kg CO2e/MMbtu
A13: 2023 | B13: July 31 | I13: Residual or Heavy Fuel Oil (# 5, 6, Navy Special & Bunker C) (MMBtu) | K13: 75.35 | L13: kg CO2e/MMbtu
A14: 2024 | B14: August 31 | I14: Biomass (MMBtu) | K14: 95.05 | L14: kg CO2e/MMbtu
A15: 2025 | B15: September 30 | I15: Renewable Natural Gas (MMBtu)
A16: 2026 | B16: October 31 | I16: Hydrogen (MMBtu)
A17: 2027 | B17: November 30 | I17: Gasoline (MMBtu) | K17: 70.66 | L17: kg CO2e/MMbtu
A18: 2028 | I18: Diesel (MMBtu) | K18: 74.21 | L18: kg CO2e/MMbtu
A19: 2029 | I19: Biodiesel (MMBtu)
A20: 2030 | I20: Compressed Natural Gas (CNG) (MMBtu) | K20: 53.11 | L20: kg CO2e/MMbtu
I21: Liquified Natural Gas (LNG) (MMBtu) | K21: 53.11 | L21: kg CO2e/MMbtu
I22: Ethanol Fuel Blend (E85) (MMBtu) | K22: 67.34 | L22: kg CO2e/MMbtu
G24: Site to source conversion for SumProduct
G25: A (energystar.gov) | I25: MWh to MMBtu conversion
G26: Renewable Energy Generated and Used On-site (MWh) | H26: 1 | I26: 3.412
G27: Purchased or Acquired Electricity (MWh) | H27: 2.8 | I27: 3.412
G28: Physical PPAs, Competitive or Utility Products, CCAs, Self-supply (MWh) | H28: 0 | I28: 0
G29: Financial / Virtual PPAs (MWh) | H29: 0 | I29: 0
G30: Unbundled RECs (MWh) | H30: 0 | I30: 0
G31: Remaining Grid Electricity (MWh) | H31: 0 | I31: 0
G32: District Steam (MMBtu) | H32: 1.2 | I32: 1
G33: District Hot Water (MMBtu) | H33: 1.2 | I33: 1
G34: District Chilled Water (MMBtu) | H34: 0.91 | I34: 1
G35: Natural Gas (MMBtu) | H35: 1.05 | I35: 1
G36: Distillate or Light Fuel Oil (#1, 2, & 4) (MMBtu) | H36: 1.01 | I36: 1
G37: Propane (MMBtu) | H37: 1.01 | I37: 1
... G51: Other Fuel (please specify) (MMBtu) | H51: 1 | I51: 1

Sheet US Emission Factors
A1: effective December 11, 2022 | B1: Historical Greenhouse Gas Factors, 2000 - 2022 | ENERGY STAR
A2: US Emissions Factors (kg CO2eq/MBtu)
A4: Fuel Type | B4: Subregion | C4: 2000 | D4: 2001 | E4: 2002 | F4: 2003 | G4: 2004 | H4: 2005 | I4: 2006 | J4: 2007 | K4: 2008 | L4: 2009 | M4: 2010 | N4: 2011 | O4: 2012 | P4: 2013 | Q4: 2014 | R4: 2015 | S4: 2016 | T4: 2017 | U4: 2018 | V4: 2019 | W4: 2020 | X4: 2021 | Y4: 2022
A5: Direct GHG Emissions
A6: Natural Gas | C6: 53.072 | D6: 53.072 | E6: 53.072 | F6: 53.072 | G6: 53.072 | H6: 53.072 | I6: 53.072 | J6: 53.072 | K6: 53.072 | L6: 53.072 | M6: 53.072 | N6: 53.072 | O6: 53.072 | P6: 53.072 | Q6: 53.1148 | R6: 53.1148 | S6: 53.1148 | T6: 53.1148 | U6: 53.1148 | V6: 53.1148 | W6: 53.1148 | X6: 53.1148 | Y6: 53.1148
A7: Propane | C7: 61.49562 | D7: 61.49562 | E7: 61.49562 | F7: 61.49562 | G7: 61.49562 | H7: 61.49562 | I7: 61.49562 | J7: 61.49562 | K7: 61.49562 | L7: 61.49562 | M7: 61.49562 | N7: 61.49562 | O7: 61.49562 | P7: 61.49562 | Q7: 61.49562 | R7: 64.248 | S7: 64.248 | T7: 64.248 | U7: 64.248 | V7: 64.248 | W7: 64.248 | X7: 64.248 | Y7: 64.248
A8: Fuel Oil (No. 1) | C8: 73.499 | D8: 73.499 | E8: 73.499 | F8: 73.499 | G8: 73.499 | H8: 73.499 | I8: 73.499 | J8: 73.499 | K8: 73.499 | L8: 73.499 | M8: 73.499 | N8: 73.499 | O8: 73.499 | P8: 73.499 | Q8: 73.499 | R8: 73.499 | S8: 73.499 | T8: 73.499 | U8: 73.499 | V8: 73.499 | W8: 73.499 | X8: 73.499 | Y8: 73.499
A9: Fuel Oil (No. 2) | C9: 74.209 | D9: 74.209 | E9: 74.209 | F9: 74.209 | G9: 74.209 | H9: 74.209 | I9: 74.209 | J9: 74.209 | K9: 74.209 | L9: 74.209 | M9: 74.209 | N9: 74.209 | O9: 74.209 | P9: 74.209 | Q9: 74.209 | R9: 74.209 | S9: 74.209 | T9: 74.209 | U9: 74.209 | V9: 74.209 | W9: 74.209 | X9: 74.209 | Y9: 74.209
A10: Fuel Oil (No. 4) | C10: 75.289 | D10: 75.289 | E10: 75.289 | F10: 75.289 | G10: 75.289 | H10: 75.289 | I10: 75.289 | J10: 75.289 | K10: 75.289 | L10: 75.289 | M10: 75.289 | N10: 75.289 | O10: 75.289 | P10: 75.289 | Q10: 75.289 | R10: 75.289 | S10: 75.289 | T10: 75.289 | U10: 75.289 | V10: 75.289 | W10: 75.289 | X10: 75.289 | Y10: 75.289
A11: Fuel Oil (No. 5 & No. 6) | C11: 75.349 | D11: 75.349 | E11: 75.349 | F11: 75.349 | G11: 75.349 | H11: 75.349 | I11: 75.349 | J11: 75.349 | K11: 75.349 | L11: 75.349 | M11: 75.349 | N11: 75.349 | O11: 75.349 | P11: 75.349 | Q11: 75.349 | R11: 75.349 | S11: 75.349 | T11: 75.349 | U11: 75.349 | V11: 75.349 | W11: 75.349 | X11: 75.349 | Y11: 75.349
A12: Diesel | C12: 74.209 | D12: 74.209 | E12: 74.209 | F12: 74.209 | G12: 74.209 | H12: 74.209 | I12: 74.209 | J12: 74.209 | K12: 74.209 | L12: 74.209 | M12: 74.209 | N12: 74.209 | O12: 74.209 | P12: 74.209 | Q12: 74.209 | R12: 74.209 | S12: 74.209 | T12: 74.209 | U12: 74.209 | V12: 74.209 | W12: 74.209 | X12: 74.209 | Y12: 74.209
A13: Coal (anthracite) | C13: 104.267 | D13: 104.267 | E13: 104.267 | F13: 104.267 | G13: 104.267 | H13: 104.267 | I13: 104.267 | J13: 104.267 | K13: 104.267 | L13: 104.267 | M13: 104.267 | N13: 104.267 | O13: 104.267 | P13: 104.267 | Q13: 104.4418 | R13: 104.4418 | S13: 104.4418 | T13: 104.4418 | U13: 104.4418 | V13: 104.4418 | W13: 104.4418 | X13: 104.4418 | Y13: 104.4418
A14: Coal (bituminous) | C14: 94.127 | D14: 94.127 | E14: 94.127 | F14: 94.127 | G14: 94.127 | H14: 94.127 | I14: 94.127 | J14: 94.127 | K14: 94.127 | L14: 94.127 | M14: 94.127 | N14: 94.127 | O14: 94.127 | P14: 94.127 | Q14: 94.0318 | R14: 94.0318 | S14: 94.0318 | T14: 94.0318 | U14: 94.0318 | V14: 94.0318 | W14: 94.0318 | X14: 94.0318 | Y14: 94.0318
A15: Coke | C15: 102.767 | D15: 102.767 | E15: 102.767 | F15: 102.767 | G15: 102.767 | H15: 102.767 | I15: 102.767 | J15: 102.767 | K15: 102.767 | L15: 102.767 | M15: 102.767 | N15: 102.767 | O15: 102.767 | P15: 102.767 | Q15: 114.4218 | R15: 114.4218 | S15: 114.4218 | T15: 114.4218 | U15: 114.4218 | V15: 114.4218 | W15: 114.4218 | X15: 114.4218 | Y15: 114.4218
A16: Kerosene | C16: 77.69 | D16: 77.69 | E16: 77.69 | F16: 77.69 | G16: 77.69 | H16: 77.69 | I16: 77.69 | J16: 77.69 | K16: 77.69 | L16: 77.69 | M16: 77.69 | N16: 77.69 | O16: 77.69 | P16: 77.69 | Q16: 77.69 | R16: 77.69 | S16: 77.69 | T16: 77.69 | U16: 77.69 | V16: 77.69 | W16: 77.69 | X16: 77.69 | Y16: 77.69
A17: Indirect GHG Emissions - District Fuels
A18: District Steam | C18: 88.538479 | D18: 88.538479 | E18: 88.538479 | F18: 88.538479 | G18: 88.538479 | H18: 88.538479 | I18: 88.538479 | J18: 88.538479 | K18: 88.538479 | L18: 88.538479 | M18: 88.538479 | N18: 88.538479 | O18: 88.538479 | P18: 88.538479 | Q18: 66.3985 | R18: 66.3985 | S18: 66.3985 | T18: 66.3985 | U18: 66.3985 | V18: 66.3985 | W18: 66.3985 | X18: 66.3985 | Y18: 66.3985
A19: District Hot Water | C19: 88.538479 | D19: 88.538479 | E19: 88.538479 | F19: 88.538479 | G19: 88.538479 | H19: 88.538479 | I19: 88.538479 | J19: 88.538479 | K19: 88.538479 | L19: 88.538479 | M19: 88.538479 | N19: 88.538479 | O19: 88.538479 | P19: 88.538479 | Q19: 66.3985 | R19: 66.3985 | S19: 66.3985 | T19: 66.3985 | U19: 66.3985 | V19: 66.3985 | W19: 66.3985 | X19: 66.3985 | Y19: 66.3985
A20: District Chilled Water - Electric Driven Chiller | C20: 52.70475 | D20: 52.70475 | E20: 52.70475 | F20: 52.70475 | G20: 52.70475 | H20: 52.70475 | I20: 52.70475 | J20: 52.70475 | K20: 52.70475 | L20: 52.70475 | M20: 52.70475 | N20: 52.70475 | O20: 52.70475 | P20: 52.70475 | Q20: 52.70475 | R20: 52.700417 | S20: 52.700417 | T20: 52.700417 | U20: 52.700417 | V20: 52.700417 | W20: 52.700417 | X20: 52.700417 | Y20: 52.700417
A21: District Chilled Water - Absorption Chiller using Natural Gas | C21: 73.863583 | D21: 73.863583 | E21: 73.863583 | F21: 73.863583 | G21: 73.863583 | H21: 73.863583 | I21: 73.863583 | J21: 73.863583 | K21: 73.863583 | L21: 73.863583 | M21: 73.863583 | N21: 73.863583 | O21: 73.863583 | P21: 73.863583 | Q21: 73.863583 | R21: 73.88925 | S21: 73.88925 | T21: 73.88925 | U21: 73.88925 | V21: 73.88925 | W21: 73.88925 | X21: 73.88925 | Y21: 73.88925
A22: District Chilled Water - Engine-Driven Chiller Natural Gas | C22: 49.2905 | D22: 49.2905 | E22: 49.2905 | F22: 49.2905 | G22: 49.2905 | H22: 49.2905 | I22: 49.2905 | J22: 49.2905 | K22: 49.2905 | L22: 49.2905 | M22: 49.2905 | N22: 49.2905 | O22: 49.2905 | P22: 49.2905 | Q22: 49.2905 | R22: 49.308167 | S22: 49.308167 | T22: 49.308167 | U22: 49.308167 | V22: 49.308167 | W22: 49.308167 | X22: 49.308167 | Y22: 49.308167
A23: Biomass GHG Emissions
A24: Wood | C24: 95.774 | D24: 95.774 | E24: 95.774 | F24: 95.774 | G24: 95.774 | H24: 95.774 | I24: 95.774 | J24: 95.774 | K24: 95.774 | L24: 95.774 | M24: 95.774 | N24: 95.774 | O24: 95.774 | P24: 95.774 | Q24: 95.0528 | R24: 95.0528 | S24: 94.22266 | T24: 94.22266 | U24: 95.0528 | V24: 95.0528 | W24: 95.0528 | X24: 95.0528 | Y24: 95.0528
A25: Indirect GHG Emissions - Electricity
A26: Electricity - Grid | B26: AKGD | C26: 164.16601 | D26: 164.16601 | E26: 164.16601 | F26: 164.16601 | G26: 164.16601 | H26: 164.16601 | I26: 164.16601 | J26: 171.16628 | K26: 171.16628 | L26: 170.66486 | M26: 167.44986 | N26: 167.44986 | O26: 169.04505 | P26: 169.04505 | Q26: 123.59427 | R26: 123.59427 | S26: 143.20667 | T26: 143.20667 | U26: 138.91541 | V26: 148.99505 | W26: 146.78541 | X26: 146.78541 | Y26: 146.78541
A27: Electricity - Grid | B27: AKMS | C27: 66.546171 | D27: 66.546171 | E27: 66.546171 | F27: 66.546171 | G27: 66.546171 | H27: 66.546171 | I27: 66.546171 | J27: 71.46446 | K27: 71.46446 | L27: 69.531083 | M27: 59.834539 | N27: 59.834539 | O27: 64.162398 | P27: 64.162398 | Q27: 90.809757 | R27: 90.809757 | S27: 67.112666 | T27: 67.112666 | U27: 70.051722 | V27: 73.283766 | W27: 71.267676 | X27: 71.267676 | Y27: 71.267676
A28: Electricity - Grid | B28: AZNM | C28: 175.05275 | D28: 175.05275 | E28: 175.05275 | F28: 175.05275 | G28: 175.05275 | H28: 175.05275 | I28: 175.05275 | J28: 167.25086 | K28: 167.25086 | L28: 159.06746 | M28: 157.24749 | N28: 157.24749 | O28: 153.93352 | P28: 153.93352 | Q28: 116.96561 | R28: 116.96561 | S28: 139.45499 | T28: 139.45499 | U28: 136.59689 | V28: 127.20305 | W28: 113.01558 | X28: 113.01558 | Y28: 113.01558
A29: Electricity - Grid | B29: CAMX | C29: 96.681168 | D29: 96.681168 | E29: 96.681168 | F29: 96.681168 | G29: 96.681168 | H29: 96.681168 | I29: 96.681168 | J29: 90.86531 | K29: 90.86531 | L29: 87.896969 | M29: 81.526853 | N29: 81.526853 | O29: 86.769621 | P29: 86.769621 | Q29: 75.837842 | R29: 75.837842 | S29: 70.440689 | T29: 70.440689 | U29: 66.292724 | V29: 60.518701 | W29: 68.52563 | X29: 68.52563 | Y29: 68.52563
A30: Electricity - Grid | B30: ERCT | C30: 176.71289 | D30: 176.71289 | E30: 176.71289 | F30: 176.71289 | G30: 176.71289 | H30: 176.71289 | I30: 176.71289 | J30: 167.13566 | K30: 167.13566 | L30: 157.67931 | M30: 162.56372 | N30: 162.56372 | O30: 152.50428 | P30: 152.50428 | Q30: 152.61567 | R30: 152.61567 | S30: 134.80599 | T30: 134.80599 | U30: 124.43787 | V30: 115.97086 | W30: 109.27759 | X30: 109.27759 | Y30: 109.27759
A31: Electricity - Grid | B31: FRCC | C31: 176.10778 | D31: 176.10778 | E31: 176.10778 | F31: 176.10778 | G31: 176.10778 | H31: 176.10778 | I31: 176.10778 | J31: 162.9387 | K31: 162.9387 | L31: 157.07918 | M31: 159.76013 | N31: 159.76013 | O31: 150.19789 | P31: 150.19789 | Q31: 143.67168 | R31: 143.67168 | S31: 135.10868 | T31: 135.10868 | U31: 124.44625 | V31: 114.92679 | W31: 111.42927 | X31: 111.42927 | Y31: 111.42927
A32: Electricity - Grid | B32: HIMS | C32: 204.2893 | D32: 204.2893 | E32: 204.2893 | F32: 204.2893 | G32: 204.2893 | H32: 204.2893 | I32: 204.2893 | J32: 179.91271 | K32: 179.91271 | L32: 180.45395 | M32: 177.6037 | N32: 177.6037 | O32: 160.24769 | P32: 160.24769 | Q32: 125.95931 | R32: 125.95931 | S32: 154.03262 | T32: 154.03262 | U32: 148.76428 | V32: 158.93658 | W32: 153.02444 | X32: 153.02444 | Y32: 153.02444
A33: Electricity - Grid | B33: HIOA | C33: 242.17403 | D33: 242.17403 | E33: 242.17403 | F33: 242.17403 | G33: 242.17403 | H33: 242.17403 | I33: 242.17403 | J33: 216.57052 | K33: 216.57052 | L33: 213.00129 | M33: 216.80297 | N33: 216.80297 | O33: 210.69563 | P33: 210.69563 | Q33: 198.12151 | R33: 198.12151 | S33: 222.69557 | T33: 222.69557 | U33: 223.67556 | V33: 226.99628 | W33: 221.40065 | X33: 221.40065 | Y33: 221.40065
A34: Electricity - Grid | B34: MROE | C34: 245.19256 | D34: 245.19256 | E34: 245.19256 | F34: 245.19256 | G34: 245.19256 | H34: 245.19256 | I34: 245.19256 | J34: 226.24578 | K34: 226.24578 | L34: 212.76723 | M34: 215.33373 | N34: 215.33373 | O34: 203.52354 | P34: 203.52354 | Q34: 222.86932 | R34: 222.86932 | S34: 223.23648 | T34: 223.23648 | U34: 224.61342 | V34: 201.07705 | W34: 204.16512 | X34: 204.16512 | Y34: 204.16512
A35: Electricity - Grid | B35: MROW | C35: 243.49602 | D35: 243.49602 | E35: 243.49602 | F35: 243.49602 | G35: 243.49602 | H35: 243.49602 | I35: 243.49602 | J35: 230.2868 | K35: 230.2868 | L35: 217.72366 | M35: 205.39886 | N35: 205.39886 | O35: 190.52834 | P35: 190.52834 | Q35: 182.86591 | R35: 182.86591 | S35: 165.82633 | T35: 165.82633 | U35: 166.06229 | V35: 147.08545 | W35: 131.15799 | X35: 131.15799 | Y35: 131.15799
A36: Electricity - Grid | B36: NEWE | C36: 124.28234 | D36: 124.28234 | E36: 124.28234 | F36: 124.28234 | G36: 124.28234 | H36: 124.28234 | I36: 124.28234 | J36: 110.90501 | K36: 110.90501 | L36: 97.613107 | M36: 96.72376 | N36: 96.72376 | O36: 85.443739 | P36: 85.443739 | Q36: 76.671476 | R36: 76.671476 | S36: 74.937607 | T36: 74.937607 | U36: 70.131616 | V36: 65.64706 | W36: 70.851457 | X36: 70.851457 | Y36: 70.851457
A37: Electricity - Grid | B37: NWPP | C37: 120.59296 | D37: 120.59296 | E37: 120.59296 | F37: 120.59296 | G37: 120.59296 | H37: 120.59296 | I37: 120.59296 | J37: 114.77092 | K37: 114.77092 | L37: 109.45907 | M37: 112.59163 | N37: 112.59163 | O37: 88.964509 | P37: 88.964509 | Q37: 121.42571 | R37: 121.42571 | S37: 87.126399 | T37: 87.126399 | U37: 85.525333 | V37: 95.696174 | W37: 80.264172 | X37: 80.264172 | Y37: 80.264172
... A53: Electricity - Grid | B53: National | C53: 177.62357 | D53: 177.62357 | E53: 177.62357 | F53: 177.62357 | G53: 177.62357 | H53: 177.62357 | I53: 177.62357 | J53: 172.77004 | K53: 172.77004 | L53: 162.48488 | M53: 164.64184 | N53: 164.64184 | O53: 151.80471 | P53: 151.80471 | Q53: 150.23932 | R53: 150.23932 | S53: 133.48874 | T53: 133.48874 | U53: 126.67051 | V53: 118.20749 | W53: 109.35496 | X53: 109.35496 | Y53: 109.35496
A54: Data Source for Period Ending Date | C54: eGRID 2005 | D54: eGRID 2005 | E54: eGRID 2005 | F54: eGRID 2005 | G54: eGRID 2005 | H54: eGRID 2005 | I54: eGRID 2005 | J54: eGRID 2007 | K54: eGRID 2007 | L54: eGRID 2009 | M54: eGRID 2010 | N54: eGRID 2010 | O54: eGRID 2012 | P54: eGRID 2012 | Q54: eGRID 2014 | R54: eGRID 2014 | S54: eGRID 2016 | T54: eGRID 2016 | U54: eGRID 2018 | V54: eGRID 2019 | W54: eGRID 2020 | X54: eGRID 2020 | Y54: eGRID 2020
A55: * eGRID region PRMS (Puerto Rico) uses version eGRID2019 for all years before 2019
A57: Sources for emissions factors:
...
