Workbook
Name Array_ElectricalChargeData: 'Electricity Meters'!$O$3:$AR$202
Name Array_ElectricalCharges: HIDE_ELEC!$B$17:$P$216
Name Array_EmissionChargeData: 'Other Emission Meters'!$K$3:$T$202
Name Array_EmissionCharges: HIDE_EMISSION!$B$3:$F$201
Name Array_MobileChargeData: 'Mobile Fuel Meters'!$R$3:$AA$202
Name Array_MobileCharges: HIDE_MOBILE!$B$16:$F$215
Name Array_OtherEnergyChargeData: 'Other Energy Meters'!$O$3:$X$202
Name Array_OtherEnergyCharges: HIDE_ENERGY!$B$25:$F$224
Name Array_PredictorsLookup: HIDE_PREDICT!$B$15:$P$214
Name Array_StationaryChargeData: 'Stationary Fuel Meters'!$P$3:$AS$202
Name Array_StationaryCharges: HIDE_STATIONARY!$B$37:$P$236
Name Array_WaterChargeData: 'Water Meters'!$M$3:$AF$202
Name Array_WaterCharges: HIDE_WATER!$B$15:$K$214
Name List_ChargeNumbers_Electricial: HIDE_ELEC!$B$15:$P$16
Name List_ChargeNumbers_Emissions: HIDE_EMISSION!$A$1:$F$2
Name List_ChargeNumbers_Mobile: HIDE_MOBILE!$B$14:$F$15
Name List_ChargeNumbers_OtherEnergy: HIDE_ENERGY!$B$23:$F$24
Name List_ChargeNumbers_Stationary: HIDE_STATIONARY!$B$35:$P$36
Name List_ChargeNumbers_Water: HIDE_WATER!$A$13:$K$14
Name List_ElectricityMeters: HIDE_ELEC!$A$17:$A$216
Name List_EmissionMeters: HIDE_EMISSION!$A$3:$A$201
Name List_Facilities: HIDE_FACILITIES!$F$2:$F$101
Name List_MobileFuelMeters: HIDE_MOBILE!$A$16:$A$215
Name List_OtherEnergyMeters: HIDE_ENERGY!$A$25:$A$224
Name List_PredictorFacilities: HIDE_PREDICT!$A$15:$A$214
Name List_PredictorNumbers: HIDE_PREDICT!$B$13:$P$14
Name List_Predictors: 'Predictor Setup'!$B$3:$B$202
Name List_StationaryFuelMeters: HIDE_STATIONARY!$A$37:$A$236
Name List_WaterMeters: HIDE_WATER!$A$15:$A$214
Name NAIC_2: HIDE_FACILITIES!$C$2:$C$21
Name NAIC_3: HIDE_FACILITIES!$D$2:$D$100
Name NAIC_3_11: HIDE_FACILITIES!$D$2:$D$6
Name NAIC_3_21: HIDE_FACILITIES!$D$7:$D$9
Name NAIC_3_22: HIDE_FACILITIES!$D$10
Name NAIC_3_23: HIDE_FACILITIES!$D$11:$D$13
Name NAIC_3_31: HIDE_FACILITIES!$D$14:$D$34
Name NAIC_3_42: HIDE_FACILITIES!$D$35:$D$37
Name NAIC_3_44: HIDE_FACILITIES!$D$38:$D$49
Name NAIC_3_48: HIDE_FACILITIES!$D$50:$D$60
Name NAIC_3_51: HIDE_FACILITIES!$D$61:$D$66
Name NAIC_3_52: HIDE_FACILITIES!$D$67:$D$71
Name NAIC_3_53: HIDE_FACILITIES!$D$72:$D$74
Name NAIC_3_54: HIDE_FACILITIES!$D$75
Name NAIC_3_55: HIDE_FACILITIES!$D$76
Name NAIC_3_56: HIDE_FACILITIES!$D$77:$D$78
Name NAIC_3_61: HIDE_FACILITIES!$D$79:$D$80
Name NAIC_3_62: HIDE_FACILITIES!$D$81:$D$83
Name NAIC_3_71: HIDE_FACILITIES!$D$84:$D$86
Name NAIC_3_72: HIDE_FACILITIES!$D$87:$D$88
Name NAIC_3_81: HIDE_FACILITIES!$D$89:$D$92
Name NAIC_3_92: HIDE_FACILITIES!$D$93:$D$100
Name Option_VehicleType: HIDE_MOBILE!$A$2:$A$12
Name Options_Calendarizing: HIDE_ELEC!$B$2:$B$4
Name Options_Countries: HIDE_FACILITIES!$A$2:$A$250
Name Options_ElecAgreementType: HIDE_ELEC!$A$2:$A$9
Name Options_ElectricityChargeTypes: HIDE_ELEC!$E$2:$E$7
Name Options_FuelsGas: HIDE_STATIONARY!$B$2:$B$10
Name Options_FuelsLiquid: HIDE_STATIONARY!$C$2:$C$32
Name Options_FuelsMaterial: HIDE_MOBILE!$E$2:$E$4
Name Options_FuelsNonRoad: HIDE_MOBILE!$D$2:$D$6

Sheet OVERVIEW
D2: VERIFI - Data Upload Template Version: 3.2 Release: 03/02/2026
B4: This template is for bulk data upload to VERIFI including adding facilities, meters, and data. It can also be used for bulk updating - please just add data to the bottom of each data sheet.
B6: Updates (03/02/2026)
B8: The VERIFI template has been updated to simplify the upload process, reduce troubleshooting needs, and accommodate the wide variety of charges that can occur on utility bills. The latest update simplifies the initially displayed tabs. Please see the below for help on getting started with this new template.
B10: Getting Started
B12: This template can be used for setting up your account or for updating your data every month if you choose to not enter data manually within VERIFI.
B14: > When uploading with this template, you have the choice of replacing existing data if you updated previous readings or only upload new data.
B15: > When entering data in this template, there is no need to sort by meter or read date. VERIFI uses the meter number and date column to parse data appropriately.
B17: This worksheet is password protected to protect formatting and features. If you need to unlock and modify the column widths or other things to better match your needs, the password is "VERIFI". PLEASE DO NOT change any column names as this will break VERIFI's ability to import data from this file.
B19: Input Guide
D21: Cell is not active or not applicable
D22: Cell is free data entry
D23: Cell is a dropdown
D24: Cell is autofilled
D25: Cell is mandatory and is blank (in error)
D26: Cell is suggested but not required and is blank
B28: Facilities
B29: Start here! This is where you will setup and input information about the different facilities in your company.
B31: Data Tabs
B32: By default, the VERIFI template shows Meter and Data tabs for electricity and stationary fuels, plus predictors. If you want to track something beyond these, please right click the tab area and unhide the TWO tabs for each additional trackable group (mobile fuels, other energy, and water)
B33: Electricity: All electricity-based energy streams including grid purchased electricity, on-site generation, and other electricity financial agreements Stationary Fuels: All fuels burned in stationary systems (e.g., natural gas, diesel, coal, propane) Mobile Fuels: All fuels burned in mobile systems, usage estimated via direct consumption or miles driven Other Energy: Other utilities purchased where the energetic transformation occurred over the fence (e.g., steam, compressed air, chilled water) Other: Refrigerant and process losses Water: Water supply and discharge utilities
B35: "---- Meters" Tabs
B36: Each meter type has a its own setup tab. This is where you enter data on the meters you want to track in your facilities. You can group similar meters together using the "Meter Group" column so that you can combine, for example, all your office building electricity meters together for analysis. You can also use the optional cost columns to track different charges on your bills over time.
B38: "----" Tabs
B39: After setting up your meters, each meter type has its own data input tab. These tabs allow you to input utility data from your bills into VERIFI. Each row will correspond to one reading for each of the meters you setup in the meter setup tabs.
B41: Predictors
B42: This tab is where you enter data about any predictors you will use for correlation or regression analysis (e.g., production data, weather data). Predictors are associated with a facility and are not calendarized. Please enter only 1 row of predictor data for each month for each facility.
B44: "HIDE" Tabs
B45: There are many hidden tabs used to make this template work. You may need to unhide these tabs to troubleshoot any errors that may occur in this template.

Sheet Facilities
A1: √ Facility Setup
A2: Facility Name | B2: Address | C2: Country | D2: U.S. State | E2: City | F2: ZIP Code | G2: NAICS Code (2-digit) | H2: NAICS Code (3-digit) | I2: Contact Name | J2: Contact Phone | K2: Contact Email

Sheet HIDE_FACILITIES
A1: Countries | B1: States | C1: 2 Digit NAIC | D1: 3 Digit NAIC | F1: Facilities
A2: United States of America (the) | B2: ALABAMA | C2: 11 - Agriculture | D2: 111 - Crop Production | F2: =IF(Facilities!A3="","",Facilities!A3)
A3: Afghanistan | B3: ALASKA | C3: 21 - Mining | D3: 112 - Animal Production and Aquaculture | F3: =IF(Facilities!A4="",F2,Facilities!A4)
A4: Albania | B4: AMERICAN SAMOA | C4: 22 - Utilities | D4: 113 - Forestry and Logging | F4: =IF(Facilities!A5="",F3,Facilities!A5)
A5: Algeria | B5: ARIZONA | C5: 23 - Construction | D5: 114 - Fishing, Hunting and Trapping | F5: =IF(Facilities!A6="",F4,Facilities!A6)
A6: American Samoa | B6: ARKANSAS | C6: 31 - 33 - Manufacturing | D6: 115 - Support Activities for Agriculture and Forestr | F6: =IF(Facilities!A7="",F5,Facilities!A7)
A7: Andorra | B7: CALIFORNIA | C7: 42 - Wholesale Trade | D7: 211 - Oil and Gas Extraction | F7: =IF(Facilities!A8="",F6,Facilities!A8)
A8: Angola | B8: COLORADO | C8: 44 -45 - Retail Trade | D8: 212 - Mining (except Oil and Gas) | F8: =IF(Facilities!A9="",F7,Facilities!A9)
A9: Anguilla | B9: CONNECTICUT | C9: 48 - 49 - Transportation and Warehousing | D9: 213 - Support Activities for Mining | F9: =IF(Facilities!A10="",F8,Facilities!A10)
A10: Antarctica | B10: DELAWARE | C10: 51 - Information | D10: 221 - Utilities | F10: =IF(Facilities!A11="",F9,Facilities!A11)
A11: Antigua and Barbuda | B11: DISTRICT OF COLUMBIA | C11: 52 - Finance and Insurance | D11: 236 - Construction of Buildings | F11: =IF(Facilities!A12="",F10,Facilities!A12)
A12: Argentina | B12: FEDERATED STATES OF MICRONESIA | C12: 53 - Real Estate and Rental and Leasing | D12: 237 - Heavy and Civil Engineering Construction | F12: =IF(Facilities!A13="",F11,Facilities!A13)
A13: Armenia | B13: FLORIDA | C13: 54 - Professional | D13: 238 - Specialty Trade Contractors | F13: =IF(Facilities!A14="",F12,Facilities!A14)
A14: Aruba | B14: GEORGIA | C14: 55 - Management of Companies and Enterprises | D14: 311 - Food Manufacturing | F14: =IF(Facilities!A15="",F13,Facilities!A15)
... A21: Barbados | B21: KANSAS | C21: 92 - Public Administration | D21: 322 - Paper Manufacturing | F21: =IF(Facilities!A22="",F20,Facilities!A22)
A22: Belarus | B22: KENTUCKY | D22: 323 - Printing and Related Support Activities | F22: =IF(Facilities!A23="",F21,Facilities!A23)
A23: Belgium | B23: LOUISIANA | D23: 324 - Petroleum and Coal Products Manufacturing | F23: =IF(Facilities!A24="",F22,Facilities!A24)
A24: Belize | B24: MAINE | D24: 325 - Chemical Manufacturing | F24: =IF(Facilities!A25="",F23,Facilities!A25)
A25: Benin | B25: MARSHALL ISLANDS | D25: 326 - Plastics and Rubber Products Manufacturing | F25: =IF(Facilities!A26="",F24,Facilities!A26)
A26: Bermuda | B26: MARYLAND | D26: 327 - Nonmetallic Mineral Product Manufacturing | F26: =IF(Facilities!A27="",F25,Facilities!A27)
A27: Bhutan | B27: MASSACHUSETTS | D27: 331 - Primary Metal Manufacturing | F27: =IF(Facilities!A28="",F26,Facilities!A28)
A28: Bolivia (Plurinational State of) | B28: MICHIGAN | D28: 332 - Fabricated Metal Product Manufacturing | F28: =IF(Facilities!A29="",F27,Facilities!A29)
A29: Bonaire, Sint Eustatius and Saba | B29: MINNESOTA | D29: 333 - Machinery Manufacturing | F29: =IF(Facilities!A30="",F28,Facilities!A30)
A30: Bosnia and Herzegovina | B30: MISSISSIPPI | D30: 334 - Computer and Electronic Product Manufacturing | F30: =IF(Facilities!A31="",F29,Facilities!A31)
A31: Botswana | B31: MISSOURI | D31: 335 - Electrical Equipment, Appliance, and Component | F31: =IF(Facilities!A32="",F30,Facilities!A32)
A32: Bouvet Island | B32: MONTANA | D32: 336 - Transportation Equipment Manufacturing | F32: =IF(Facilities!A33="",F31,Facilities!A33)
A33: Brazil | B33: NEBRASKA | D33: 337 - Furniture and Related Product Manufacturing | F33: =IF(Facilities!A34="",F32,Facilities!A34)
... A60: Czechia | B60: WYOMING | D60: 493 - Warehousing and Storage | F60: =IF(Facilities!A61="",F59,Facilities!A61)
A61: Côte d"Ivoire | D61: 511 - Publishing Industries (except Internet) | F61: =IF(Facilities!A62="",F60,Facilities!A62)
A62: Denmark | D62: 512 - Motion Picture and Sound Recording Industries | F62: =IF(Facilities!A63="",F61,Facilities!A63)
A63: Djibouti | D63: 515 - Broadcasting (except Internet) | F63: =IF(Facilities!A64="",F62,Facilities!A64)
A64: Dominica | D64: 517 - Telecommunications | F64: =IF(Facilities!A65="",F63,Facilities!A65)
A65: Dominican Republic (the) | D65: 518 - Data Processing, Hosting, and Related Services | F65: =IF(Facilities!A66="",F64,Facilities!A66)
A66: Ecuador | D66: 519 - Other Information Services | F66: =IF(Facilities!A67="",F65,Facilities!A67)
A67: Egypt | D67: 521 - Monetary Authorities-Central Bank | F67: =IF(Facilities!A68="",F66,Facilities!A68)
A68: El Salvador | D68: 522 - Credit Intermediation and Related Activities | F68: =IF(Facilities!A69="",F67,Facilities!A69)
A69: Equatorial Guinea | D69: 523 - Securities, Commodity Contracts, and Other Fin | F69: =IF(Facilities!A70="",F68,Facilities!A70)
A70: Eritrea | D70: 524 - Insurance Carriers and Related Activities | F70: =IF(Facilities!A71="",F69,Facilities!A71)
A71: Estonia | D71: 525 - Funds, Trusts, and Other Financial Vehicles | F71: =IF(Facilities!A72="",F70,Facilities!A72)
A72: Eswatini | D72: 531 - Real Estate | F72: =IF(Facilities!A73="",F71,Facilities!A73)
...

Sheet Electricity Meters
A1: √ Electricity Meter Setup | O1: √ Electricity Charge Setup (Optional)
A2: Facility Name | B2: Meter Number (UNIQUE) | C2: Meter Name (DISPLAY) | D2: Meter Group (ANALYSIS) | E2: Calendarize Readings? | F2: Unit (USAGE) | G2: Unit (DEMAND) | H2: S2S Factor | I2: Agreement Type | J2: Retain RECs? | K2: Account # | L2: Supplier | M2: Location | N2: Notes | O2: ="Charge "&QUOTIENT(COLUMN()-13,2)&" Name" -> Charge 1 Name | P2: ="Charge "&QUOTIENT(COLUMN()-13,2)&" Type" -> Charge 1 Type | Q2: ="Charge "&QUOTIENT(COLUMN()-13,2)&" Name" -> Charge 2 Name | R2: ="Charge "&QUOTIENT(COLUMN()-13,2)&" Type" -> Charge 2 Type | S2: ="Charge "&QUOTIENT(COLUMN()-13,2)&" Name" -> Charge 3 Name | T2: ="Charge "&QUOTIENT(COLUMN()-13,2)&" Type" -> Charge 3 Type | U2: ="Charge "&QUOTIENT(COLUMN()-13,2)&" Name" -> Charge 4 Name | V2: ="Charge "&QUOTIENT(COLUMN()-13,2)&" Type" -> Charge 4 Type | W2: ="Charge "&QUOTIENT(COLUMN()-13,2)&" Name" -> Charge 5 Name | X2: ="Charge "&QUOTIENT(COLUMN()-13,2)&" Type" -> Charge 5 Type | Y2: ="Charge "&QUOTIENT(COLUMN()-13,2)&" Name" -> Charge 6 Name | Z2: ="Charge "&QUOTIENT(COLUMN()-13,2)&" Type" -> Charge 6 Type | AA2: ="Charge "&QUOTIENT(COLUMN()-13,2)&" Name" -> Charge 7 Name | AB2: ="Charge "&QUOTIENT(COLUMN()-13,2)&" Type" -> Charge 7 Type | AC2: ="Charge "&QUOTIENT(COLUMN()-13,2)&" Name" -> Charge 8 Name | AD2: ="Charge "&QUOTIENT(COLUMN()-13,2)&" Type" -> Charge 8 Type | AE2: ="Charge "&QUOTIENT(COLUMN()-13,2)&" Name" -> Charge 9 Name | AF2: ="Charge "&QUOTIENT(COLUMN()-13,2)&" Type" -> Charge 9 Type | AG2: ="Charge "&QUOTIENT(COLUMN()-13,2)&" Name" -> Charge 10 Name | AH2: ="Charge "&QUOTIENT(COLUMN()-13,2)&" Type" -> Charge 10 Type | AI2: ="Charge "&QUOTIENT(COLUMN()-13,2)&" Name" -> Charge 11 Name | AJ2: ="Charge "&QUOTIENT(COLUMN()-13,2)&" Type" -> Charge 11 Type | AK2: ="Charge "&QUOTIENT(COLUMN()-13,2)&" Name" -> Charge 12 Name | AL2: ="Charge "&QUOTIENT(COLUMN()-13,2)&" Type" -> Charge 12 Type | AM2: ="Charge "&QUOTIENT(COLUMN()-13,2)&" Name" -> Charge 13 Name | AN2: ="Charge "&QUOTIENT(COLUMN()-13,2)&" Type" -> Charge 13 Type | AO2: ="Charge "&QUOTIENT(COLUMN()-13,2)&" Name" -> Charge 14 Name | AP2: ="Charge "&QUOTIENT(COLUMN()-13,2)&" Type" -> Charge 14 Type | AQ2: ="Charge "&QUOTIENT(COLUMN()-13,2)&" Name" -> Charge 15 Name | AR2: ="Charge "&QUOTIENT(COLUMN()-13,2)&" Type" -> Charge 15 Type

Sheet Electricity
A1: √ Electricity Meter Readings | G1: √ Electricity Charges (Optional)
A2: Meter Number | B2: Read Date | C2: Total Usage | D2: Actual Demand | E2: Power Factor | F2: Total Cost ($) | G2: =IF(INDEX(List_ChargeNumbers_Electricial, 1, ROUNDUP(COLUMN()/3-2,0)) = 0,"",INDEX(List_ChargeNumbers_Electricial, 2, ROUNDUP(COLUMN()/3-2,0))&" Name") | H2: =IF(INDEX(List_ChargeNumbers_Electricial, 1, ROUNDUP(COLUMN()/3-2,0)) = 0,"",INDEX(List_ChargeNumbers_Electricial, 2, ROUNDUP(COLUMN()/3-2,0))&" Reading") | I2: =IF(INDEX(List_ChargeNumbers_Electricial, 1, ROUNDUP(COLUMN()/3-2,0)) = 0,"",INDEX(List_ChargeNumbers_Electricial, 2, ROUNDUP(COLUMN()/3-2,0))&" Cost") | J2: =IF(INDEX(List_ChargeNumbers_Electricial, 1, ROUNDUP(COLUMN()/3-2,0)) = 0,"",INDEX(List_ChargeNumbers_Electricial, 2, ROUNDUP(COLUMN()/3-2,0))&" Name") | K2: =IF(INDEX(List_ChargeNumbers_Electricial, 1, ROUNDUP(COLUMN()/3-2,0)) = 0,"",INDEX(List_ChargeNumbers_Electricial, 2, ROUNDUP(COLUMN()/3-2,0))&" Reading") | L2: =IF(INDEX(List_ChargeNumbers_Electricial, 1, ROUNDUP(COLUMN()/3-2,0)) = 0,"",INDEX(List_ChargeNumbers_Electricial, 2, ROUNDUP(COLUMN()/3-2,0))&" Cost") | M2: =IF(INDEX(List_ChargeNumbers_Electricial, 1, ROUNDUP(COLUMN()/3-2,0)) = 0,"",INDEX(List_ChargeNumbers_Electricial, 2, ROUNDUP(COLUMN()/3-2,0))&" Name") | N2: =IF(INDEX(List_ChargeNumbers_Electricial, 1, ROUNDUP(COLUMN()/3-2,0)) = 0,"",INDEX(List_ChargeNumbers_Electricial, 2, ROUNDUP(COLUMN()/3-2,0))&" Reading") | O2: =IF(INDEX(List_ChargeNumbers_Electricial, 1, ROUNDUP(COLUMN()/3-2,0)) = 0,"",INDEX(List_ChargeNumbers_Electricial, 2, ROUNDUP(COLUMN()/3-2,0))&" Cost") | P2: =IF(INDEX(List_ChargeNumbers_Electricial, 1, ROUNDUP(COLUMN()/3-2,0)) = 0,"",INDEX(List_ChargeNumbers_Electricial, 2, ROUNDUP(COLUMN()/3-2,0))&" Name") | Q2: =IF(INDEX(List_ChargeNumbers_Electricial, 1, ROUNDUP(COLUMN()/3-2,0)) = 0,"",INDEX(List_ChargeNumbers_Electricial, 2, ROUNDUP(COLUMN()/3-2,0))&" Reading") | R2: =IF(INDEX(List_ChargeNumbers_Electricial, 1, ROUNDUP(COLUMN()/3-2,0)) = 0,"",INDEX(List_ChargeNumbers_Electricial, 2, ROUNDUP(COLUMN()/3-2,0))&" Cost") | S2: =IF(INDEX(List_ChargeNumbers_Electricial, 1, ROUNDUP(COLUMN()/3-2,0)) = 0,"",INDEX(List_ChargeNumbers_Electricial, 2, ROUNDUP(COLUMN()/3-2,0))&" Name") | T2: =IF(INDEX(List_ChargeNumbers_Electricial, 1, ROUNDUP(COLUMN()/3-2,0)) = 0,"",INDEX(List_ChargeNumbers_Electricial, 2, ROUNDUP(COLUMN()/3-2,0))&" Reading") | U2: =IF(INDEX(List_ChargeNumbers_Electricial, 1, ROUNDUP(COLUMN()/3-2,0)) = 0,"",INDEX(List_ChargeNumbers_Electricial, 2, ROUNDUP(COLUMN()/3-2,0))&" Cost") | V2: =IF(INDEX(List_ChargeNumbers_Electricial, 1, ROUNDUP(COLUMN()/3-2,0)) = 0,"",INDEX(List_ChargeNumbers_Electricial, 2, ROUNDUP(COLUMN()/3-2,0))&" Name") | W2: =IF(INDEX(List_ChargeNumbers_Electricial, 1, ROUNDUP(COLUMN()/3-2,0)) = 0,"",INDEX(List_ChargeNumbers_Electricial, 2, ROUNDUP(COLUMN()/3-2,0))&" Reading") | X2: =IF(INDEX(List_ChargeNumbers_Electricial, 1, ROUNDUP(COLUMN()/3-2,0)) = 0,"",INDEX(List_ChargeNumbers_Electricial, 2, ROUNDUP(COLUMN()/3-2,0))&" Cost") | Y2: =IF(INDEX(List_ChargeNumbers_Electricial, 1, ROUNDUP(COLUMN()/3-2,0)) = 0,"",INDEX(List_ChargeNumbers_Electricial, 2, ROUNDUP(COLUMN()/3-2,0))&" Name") | Z2: =IF(INDEX(List_ChargeNumbers_Electricial, 1, ROUNDUP(COLUMN()/3-2,0)) = 0,"",INDEX(List_ChargeNumbers_Electricial, 2, ROUNDUP(COLUMN()/3-2,0))&" Reading") | AA2: =IF(INDEX(List_ChargeNumbers_Electricial, 1, ROUNDUP(COLUMN()/3-2,0)) = 0,"",INDEX(List_ChargeNumbers_Electricial, 2, ROUNDUP(COLUMN()/3-2,0))&" Cost") | AB2: =IF(INDEX(List_ChargeNumbers_Electricial, 1, ROUNDUP(COLUMN()/3-2,0)) = 0,"",INDEX(List_ChargeNumbers_Electricial, 2, ROUNDUP(COLUMN()/3-2,0))&" Name") | AC2: =IF(INDEX(List_ChargeNumbers_Electricial, 1, ROUNDUP(COLUMN()/3-2,0)) = 0,"",INDEX(List_ChargeNumbers_Electricial, 2, ROUNDUP(COLUMN()/3-2,0))&" Reading") | AD2: =IF(INDEX(List_ChargeNumbers_Electricial, 1, ROUNDUP(COLUMN()/3-2,0)) = 0,"",INDEX(List_ChargeNumbers_Electricial, 2, ROUNDUP(COLUMN()/3-2,0))&" Cost") | AE2: =IF(INDEX(List_ChargeNumbers_Electricial, 1, ROUNDUP(COLUMN()/3-2,0)) = 0,"",INDEX(List_ChargeNumbers_Electricial, 2, ROUNDUP(COLUMN()/3-2,0))&" Name") | AF2: =IF(INDEX(List_ChargeNumbers_Electricial, 1, ROUNDUP(COLUMN()/3-2,0)) = 0,"",INDEX(List_ChargeNumbers_Electricial, 2, ROUNDUP(COLUMN()/3-2,0))&" Reading") | AG2: =IF(INDEX(List_ChargeNumbers_Electricial, 1, ROUNDUP(COLUMN()/3-2,0)) = 0,"",INDEX(List_ChargeNumbers_Electricial, 2, ROUNDUP(COLUMN()/3-2,0))&" Cost") | AH2: =IF(INDEX(List_ChargeNumbers_Electricial, 1, ROUNDUP(COLUMN()/3-2,0)) = 0,"",INDEX(List_ChargeNumbers_Electricial, 2, ROUNDUP(COLUMN()/3-2,0))&" Name") | AI2: =IF(INDEX(List_ChargeNumbers_Electricial, 1, ROUNDUP(COLUMN()/3-2,0)) = 0,"",INDEX(List_ChargeNumbers_Electricial, 2, ROUNDUP(COLUMN()/3-2,0))&" Reading") | AJ2: =IF(INDEX(List_ChargeNumbers_Electricial, 1, ROUNDUP(COLUMN()/3-2,0)) = 0,"",INDEX(List_ChargeNumbers_Electricial, 2, ROUNDUP(COLUMN()/3-2,0))&" Cost") | AK2: =IF(INDEX(List_ChargeNumbers_Electricial, 1, ROUNDUP(COLUMN()/3-2,0)) = 0,"",INDEX(List_ChargeNumbers_Electricial, 2, ROUNDUP(COLUMN()/3-2,0))&" Name") | AL2: =IF(INDEX(List_ChargeNumbers_Electricial, 1, ROUNDUP(COLUMN()/3-2,0)) = 0,"",INDEX(List_ChargeNumbers_Electricial, 2, ROUNDUP(COLUMN()/3-2,0))&" Reading") | AM2: =IF(INDEX(List_ChargeNumbers_Electricial, 1, ROUNDUP(COLUMN()/3-2,0)) = 0,"",INDEX(List_ChargeNumbers_Electricial, 2, ROUNDUP(COLUMN()/3-2,0))&" Cost") | AN2: =IF(INDEX(List_ChargeNumbers_Electricial, 1, ROUNDUP(COLUMN()/3-2,0)) = 0,"",INDEX(List_ChargeNumbers_Electricial, 2, ROUNDUP(COLUMN()/3-2,0))&" Name") | AO2: =IF(INDEX(List_ChargeNumbers_Electricial, 1, ROUNDUP(COLUMN()/3-2,0)) = 0,"",INDEX(List_ChargeNumbers_Electricial, 2, ROUNDUP(COLUMN()/3-2,0))&" Reading") | AP2: =IF(INDEX(List_ChargeNumbers_Electricial, 1, ROUNDUP(COLUMN()/3-2,0)) = 0,"",INDEX(List_ChargeNumbers_Electricial, 2, ROUNDUP(COLUMN()/3-2,0))&" Cost") | AQ2: =IF(INDEX(List_ChargeNumbers_Electricial, 1, ROUNDUP(COLUMN()/3-2,0)) = 0,"",INDEX(List_ChargeNumbers_Electricial, 2, ROUNDUP(COLUMN()/3-2,0))&" Name") | AR2: =IF(INDEX(List_ChargeNumbers_Electricial, 1, ROUNDUP(COLUMN()/3-2,0)) = 0,"",INDEX(List_ChargeNumbers_Electricial, 2, ROUNDUP(COLUMN()/3-2,0))&" Reading") | AS2: =IF(INDEX(List_ChargeNumbers_Electricial, 1, ROUNDUP(COLUMN()/3-2,0)) = 0,"",INDEX(List_ChargeNumbers_Electricial, 2, ROUNDUP(COLUMN()/3-2,0))&" Cost") | AT2: =IF(INDEX(List_ChargeNumbers_Electricial, 1, ROUNDUP(COLUMN()/3-2,0)) = 0,"",INDEX(List_ChargeNumbers_Electricial, 2, ROUNDUP(COLUMN()/3-2,0))&" Name") | AU2: =IF(INDEX(List_ChargeNumbers_Electricial, 1, ROUNDUP(COLUMN()/3-2,0)) = 0,"",INDEX(List_ChargeNumbers_Electricial, 2, ROUNDUP(COLUMN()/3-2,0))&" Reading") | AV2: =IF(INDEX(List_ChargeNumbers_Electricial, 1, ROUNDUP(COLUMN()/3-2,0)) = 0,"",INDEX(List_ChargeNumbers_Electricial, 2, ROUNDUP(COLUMN()/3-2,0))&" Cost") | AW2: =IF(INDEX(List_ChargeNumbers_Electricial, 1, ROUNDUP(COLUMN()/3-2,0)) = 0,"",INDEX(List_ChargeNumbers_Electricial, 2, ROUNDUP(COLUMN()/3-2,0))&" Name") | AX2: =IF(INDEX(List_ChargeNumbers_Electricial, 1, ROUNDUP(COLUMN()/3-2,0)) = 0,"",INDEX(List_ChargeNumbers_Electricial, 2, ROUNDUP(COLUMN()/3-2,0))&" Reading") | AY2: =IF(INDEX(List_ChargeNumbers_Electricial, 1, ROUNDUP(COLUMN()/3-2,0)) = 0,"",INDEX(List_ChargeNumbers_Electricial, 2, ROUNDUP(COLUMN()/3-2,0))&" Cost")
G3: =IF(ISBLANK($A3),"",INDEX(Array_ElectricalCharges,MATCH($A3,List_ElectricityMeters,0),ROUNDUP(COLUMN()/3,0)-2)) | J3: =IF(ISBLANK($A3),"",INDEX(Array_ElectricalCharges,MATCH($A3,List_ElectricityMeters,0),ROUNDUP(COLUMN()/3,0)-2)) | M3: =IF(ISBLANK($A3),"",INDEX(Array_ElectricalCharges,MATCH($A3,List_ElectricityMeters,0),ROUNDUP(COLUMN()/3,0)-2)) | P3: =IF(ISBLANK($A3),"",INDEX(Array_ElectricalCharges,MATCH($A3,List_ElectricityMeters,0),ROUNDUP(COLUMN()/3,0)-2)) | S3: =IF(ISBLANK($A3),"",INDEX(Array_ElectricalCharges,MATCH($A3,List_ElectricityMeters,0),ROUNDUP(COLUMN()/3,0)-2)) | V3: =IF(ISBLANK($A3),"",INDEX(Array_ElectricalCharges,MATCH($A3,List_ElectricityMeters,0),ROUNDUP(COLUMN()/3,0)-2)) | Y3: =IF(ISBLANK($A3),"",INDEX(Array_ElectricalCharges,MATCH($A3,List_ElectricityMeters,0),ROUNDUP(COLUMN()/3,0)-2)) | AB3: =IF(ISBLANK($A3),"",INDEX(Array_ElectricalCharges,MATCH($A3,List_ElectricityMeters,0),ROUNDUP(COLUMN()/3,0)-2)) | AE3: =IF(ISBLANK($A3),"",INDEX(Array_ElectricalCharges,MATCH($A3,List_ElectricityMeters,0),ROUNDUP(COLUMN()/3,0)-2)) | AH3: =IF(ISBLANK($A3),"",INDEX(Array_ElectricalCharges,MATCH($A3,List_ElectricityMeters,0),ROUNDUP(COLUMN()/3,0)-2)) | AK3: =IF(ISBLANK($A3),"",INDEX(Array_ElectricalCharges,MATCH($A3,List_ElectricityMeters,0),ROUNDUP(COLUMN()/3,0)-2)) | AN3: =IF(ISBLANK($A3),"",INDEX(Array_ElectricalCharges,MATCH($A3,List_ElectricityMeters,0),ROUNDUP(COLUMN()/3,0)-2)) | AQ3: =IF(ISBLANK($A3),"",INDEX(Array_ElectricalCharges,MATCH($A3,List_ElectricityMeters,0),ROUNDUP(COLUMN()/3,0)-2)) | AT3: =IF(ISBLANK($A3),"",INDEX(Array_ElectricalCharges,MATCH($A3,List_ElectricityMeters,0),ROUNDUP(COLUMN()/3,0)-2)) | AW3: =IF(ISBLANK($A3),"",INDEX(Array_ElectricalCharges,MATCH($A3,List_ElectricityMeters,0),ROUNDUP(COLUMN()/3,0)-2))
G4: =IF(ISBLANK($A4),"",INDEX(Array_ElectricalCharges,MATCH($A4,List_ElectricityMeters,0),ROUNDUP(COLUMN()/3,0)-2)) | J4: =IF(ISBLANK($A4),"",INDEX(Array_ElectricalCharges,MATCH($A4,List_ElectricityMeters,0),ROUNDUP(COLUMN()/3,0)-2)) | M4: =IF(ISBLANK($A4),"",INDEX(Array_ElectricalCharges,MATCH($A4,List_ElectricityMeters,0),ROUNDUP(COLUMN()/3,0)-2)) | P4: =IF(ISBLANK($A4),"",INDEX(Array_ElectricalCharges,MATCH($A4,List_ElectricityMeters,0),ROUNDUP(COLUMN()/3,0)-2)) | S4: =IF(ISBLANK($A4),"",INDEX(Array_ElectricalCharges,MATCH($A4,List_ElectricityMeters,0),ROUNDUP(COLUMN()/3,0)-2)) | V4: =IF(ISBLANK($A4),"",INDEX(Array_ElectricalCharges,MATCH($A4,List_ElectricityMeters,0),ROUNDUP(COLUMN()/3,0)-2)) | Y4: =IF(ISBLANK($A4),"",INDEX(Array_ElectricalCharges,MATCH($A4,List_ElectricityMeters,0),ROUNDUP(COLUMN()/3,0)-2)) | AB4: =IF(ISBLANK($A4),"",INDEX(Array_ElectricalCharges,MATCH($A4,List_ElectricityMeters,0),ROUNDUP(COLUMN()/3,0)-2)) | AE4: =IF(ISBLANK($A4),"",INDEX(Array_ElectricalCharges,MATCH($A4,List_ElectricityMeters,0),ROUNDUP(COLUMN()/3,0)-2)) | AH4: =IF(ISBLANK($A4),"",INDEX(Array_ElectricalCharges,MATCH($A4,List_ElectricityMeters,0),ROUNDUP(COLUMN()/3,0)-2)) | AK4: =IF(ISBLANK($A4),"",INDEX(Array_ElectricalCharges,MATCH($A4,List_ElectricityMeters,0),ROUNDUP(COLUMN()/3,0)-2)) | AN4: =IF(ISBLANK($A4),"",INDEX(Array_ElectricalCharges,MATCH($A4,List_ElectricityMeters,0),ROUNDUP(COLUMN()/3,0)-2)) | AQ4: =IF(ISBLANK($A4),"",INDEX(Array_ElectricalCharges,MATCH($A4,List_ElectricityMeters,0),ROUNDUP(COLUMN()/3,0)-2)) | AT4: =IF(ISBLANK($A4),"",INDEX(Array_ElectricalCharges,MATCH($A4,List_ElectricityMeters,0),ROUNDUP(COLUMN()/3,0)-2)) | AW4: =IF(ISBLANK($A4),"",INDEX(Array_ElectricalCharges,MATCH($A4,List_ElectricityMeters,0),ROUNDUP(COLUMN()/3,0)-2))
G5: =IF(ISBLANK($A5),"",INDEX(Array_ElectricalCharges,MATCH($A5,List_ElectricityMeters,0),ROUNDUP(COLUMN()/3,0)-2)) | J5: =IF(ISBLANK($A5),"",INDEX(Array_ElectricalCharges,MATCH($A5,List_ElectricityMeters,0),ROUNDUP(COLUMN()/3,0)-2)) | M5: =IF(ISBLANK($A5),"",INDEX(Array_ElectricalCharges,MATCH($A5,List_ElectricityMeters,0),ROUNDUP(COLUMN()/3,0)-2)) | P5: =IF(ISBLANK($A5),"",INDEX(Array_ElectricalCharges,MATCH($A5,List_ElectricityMeters,0),ROUNDUP(COLUMN()/3,0)-2)) | S5: =IF(ISBLANK($A5),"",INDEX(Array_ElectricalCharges,MATCH($A5,List_ElectricityMeters,0),ROUNDUP(COLUMN()/3,0)-2)) | V5: =IF(ISBLANK($A5),"",INDEX(Array_ElectricalCharges,MATCH($A5,List_ElectricityMeters,0),ROUNDUP(COLUMN()/3,0)-2)) | Y5: =IF(ISBLANK($A5),"",INDEX(Array_ElectricalCharges,MATCH($A5,List_ElectricityMeters,0),ROUNDUP(COLUMN()/3,0)-2)) | AB5: =IF(ISBLANK($A5),"",INDEX(Array_ElectricalCharges,MATCH($A5,List_ElectricityMeters,0),ROUNDUP(COLUMN()/3,0)-2)) | AE5: =IF(ISBLANK($A5),"",INDEX(Array_ElectricalCharges,MATCH($A5,List_ElectricityMeters,0),ROUNDUP(COLUMN()/3,0)-2)) | AH5: =IF(ISBLANK($A5),"",INDEX(Array_ElectricalCharges,MATCH($A5,List_ElectricityMeters,0),ROUNDUP(COLUMN()/3,0)-2)) | AK5: =IF(ISBLANK($A5),"",INDEX(Array_ElectricalCharges,MATCH($A5,List_ElectricityMeters,0),ROUNDUP(COLUMN()/3,0)-2)) | AN5: =IF(ISBLANK($A5),"",INDEX(Array_ElectricalCharges,MATCH($A5,List_ElectricityMeters,0),ROUNDUP(COLUMN()/3,0)-2)) | AQ5: =IF(ISBLANK($A5),"",INDEX(Array_ElectricalCharges,MATCH($A5,List_ElectricityMeters,0),ROUNDUP(COLUMN()/3,0)-2)) | AT5: =IF(ISBLANK($A5),"",INDEX(Array_ElectricalCharges,MATCH($A5,List_ElectricityMeters,0),ROUNDUP(COLUMN()/3,0)-2)) | AW5: =IF(ISBLANK($A5),"",INDEX(Array_ElectricalCharges,MATCH($A5,List_ElectricityMeters,0),ROUNDUP(COLUMN()/3,0)-2))
G6: =IF(ISBLANK($A6),"",INDEX(Array_ElectricalCharges,MATCH($A6,List_ElectricityMeters,0),ROUNDUP(COLUMN()/3,0)-2)) | J6: =IF(ISBLANK($A6),"",INDEX(Array_ElectricalCharges,MATCH($A6,List_ElectricityMeters,0),ROUNDUP(COLUMN()/3,0)-2)) | M6: =IF(ISBLANK($A6),"",INDEX(Array_ElectricalCharges,MATCH($A6,List_ElectricityMeters,0),ROUNDUP(COLUMN()/3,0)-2)) | P6: =IF(ISBLANK($A6),"",INDEX(Array_ElectricalCharges,MATCH($A6,List_ElectricityMeters,0),ROUNDUP(COLUMN()/3,0)-2)) | S6: =IF(ISBLANK($A6),"",INDEX(Array_ElectricalCharges,MATCH($A6,List_ElectricityMeters,0),ROUNDUP(COLUMN()/3,0)-2)) | V6: =IF(ISBLANK($A6),"",INDEX(Array_ElectricalCharges,MATCH($A6,List_ElectricityMeters,0),ROUNDUP(COLUMN()/3,0)-2)) | Y6: =IF(ISBLANK($A6),"",INDEX(Array_ElectricalCharges,MATCH($A6,List_ElectricityMeters,0),ROUNDUP(COLUMN()/3,0)-2)) | AB6: =IF(ISBLANK($A6),"",INDEX(Array_ElectricalCharges,MATCH($A6,List_ElectricityMeters,0),ROUNDUP(COLUMN()/3,0)-2)) | AE6: =IF(ISBLANK($A6),"",INDEX(Array_ElectricalCharges,MATCH($A6,List_ElectricityMeters,0),ROUNDUP(COLUMN()/3,0)-2)) | AH6: =IF(ISBLANK($A6),"",INDEX(Array_ElectricalCharges,MATCH($A6,List_ElectricityMeters,0),ROUNDUP(COLUMN()/3,0)-2)) | AK6: =IF(ISBLANK($A6),"",INDEX(Array_ElectricalCharges,MATCH($A6,List_ElectricityMeters,0),ROUNDUP(COLUMN()/3,0)-2)) | AN6: =IF(ISBLANK($A6),"",INDEX(Array_ElectricalCharges,MATCH($A6,List_ElectricityMeters,0),ROUNDUP(COLUMN()/3,0)-2)) | AQ6: =IF(ISBLANK($A6),"",INDEX(Array_ElectricalCharges,MATCH($A6,List_ElectricityMeters,0),ROUNDUP(COLUMN()/3,0)-2)) | AT6: =IF(ISBLANK($A6),"",INDEX(Array_ElectricalCharges,MATCH($A6,List_ElectricityMeters,0),ROUNDUP(COLUMN()/3,0)-2)) | AW6: =IF(ISBLANK($A6),"",INDEX(Array_ElectricalCharges,MATCH($A6,List_ElectricityMeters,0),ROUNDUP(COLUMN()/3,0)-2))
G7: =IF(ISBLANK($A7),"",INDEX(Array_ElectricalCharges,MATCH($A7,List_ElectricityMeters,0),ROUNDUP(COLUMN()/3,0)-2)) | J7: =IF(ISBLANK($A7),"",INDEX(Array_ElectricalCharges,MATCH($A7,List_ElectricityMeters,0),ROUNDUP(COLUMN()/3,0)-2)) | M7: =IF(ISBLANK($A7),"",INDEX(Array_ElectricalCharges,MATCH($A7,List_ElectricityMeters,0),ROUNDUP(COLUMN()/3,0)-2)) | P7: =IF(ISBLANK($A7),"",INDEX(Array_ElectricalCharges,MATCH($A7,List_ElectricityMeters,0),ROUNDUP(COLUMN()/3,0)-2)) | S7: =IF(ISBLANK($A7),"",INDEX(Array_ElectricalCharges,MATCH($A7,List_ElectricityMeters,0),ROUNDUP(COLUMN()/3,0)-2)) | V7: =IF(ISBLANK($A7),"",INDEX(Array_ElectricalCharges,MATCH($A7,List_ElectricityMeters,0),ROUNDUP(COLUMN()/3,0)-2)) | Y7: =IF(ISBLANK($A7),"",INDEX(Array_ElectricalCharges,MATCH($A7,List_ElectricityMeters,0),ROUNDUP(COLUMN()/3,0)-2)) | AB7: =IF(ISBLANK($A7),"",INDEX(Array_ElectricalCharges,MATCH($A7,List_ElectricityMeters,0),ROUNDUP(COLUMN()/3,0)-2)) | AE7: =IF(ISBLANK($A7),"",INDEX(Array_ElectricalCharges,MATCH($A7,List_ElectricityMeters,0),ROUNDUP(COLUMN()/3,0)-2)) | AH7: =IF(ISBLANK($A7),"",INDEX(Array_ElectricalCharges,MATCH($A7,List_ElectricityMeters,0),ROUNDUP(COLUMN()/3,0)-2)) | AK7: =IF(ISBLANK($A7),"",INDEX(Array_ElectricalCharges,MATCH($A7,List_ElectricityMeters,0),ROUNDUP(COLUMN()/3,0)-2)) | AN7: =IF(ISBLANK($A7),"",INDEX(Array_ElectricalCharges,MATCH($A7,List_ElectricityMeters,0),ROUNDUP(COLUMN()/3,0)-2)) | AQ7: =IF(ISBLANK($A7),"",INDEX(Array_ElectricalCharges,MATCH($A7,List_ElectricityMeters,0),ROUNDUP(COLUMN()/3,0)-2)) | AT7: =IF(ISBLANK($A7),"",INDEX(Array_ElectricalCharges,MATCH($A7,List_ElectricityMeters,0),ROUNDUP(COLUMN()/3,0)-2)) | AW7: =IF(ISBLANK($A7),"",INDEX(Array_ElectricalCharges,MATCH($A7,List_ElectricityMeters,0),ROUNDUP(COLUMN()/3,0)-2))
G8: =IF(ISBLANK($A8),"",INDEX(Array_ElectricalCharges,MATCH($A8,List_ElectricityMeters,0),ROUNDUP(COLUMN()/3,0)-2)) | J8: =IF(ISBLANK($A8),"",INDEX(Array_ElectricalCharges,MATCH($A8,List_ElectricityMeters,0),ROUNDUP(COLUMN()/3,0)-2)) | M8: =IF(ISBLANK($A8),"",INDEX(Array_ElectricalCharges,MATCH($A8,List_ElectricityMeters,0),ROUNDUP(COLUMN()/3,0)-2)) | P8: =IF(ISBLANK($A8),"",INDEX(Array_ElectricalCharges,MATCH($A8,List_ElectricityMeters,0),ROUNDUP(COLUMN()/3,0)-2)) | S8: =IF(ISBLANK($A8),"",INDEX(Array_ElectricalCharges,MATCH($A8,List_ElectricityMeters,0),ROUNDUP(COLUMN()/3,0)-2)) | V8: =IF(ISBLANK($A8),"",INDEX(Array_ElectricalCharges,MATCH($A8,List_ElectricityMeters,0),ROUNDUP(COLUMN()/3,0)-2)) | Y8: =IF(ISBLANK($A8),"",INDEX(Array_ElectricalCharges,MATCH($A8,List_ElectricityMeters,0),ROUNDUP(COLUMN()/3,0)-2)) | AB8: =IF(ISBLANK($A8),"",INDEX(Array_ElectricalCharges,MATCH($A8,List_ElectricityMeters,0),ROUNDUP(COLUMN()/3,0)-2)) | AE8: =IF(ISBLANK($A8),"",INDEX(Array_ElectricalCharges,MATCH($A8,List_ElectricityMeters,0),ROUNDUP(COLUMN()/3,0)-2)) | AH8: =IF(ISBLANK($A8),"",INDEX(Array_ElectricalCharges,MATCH($A8,List_ElectricityMeters,0),ROUNDUP(COLUMN()/3,0)-2)) | AK8: =IF(ISBLANK($A8),"",INDEX(Array_ElectricalCharges,MATCH($A8,List_ElectricityMeters,0),ROUNDUP(COLUMN()/3,0)-2)) | AN8: =IF(ISBLANK($A8),"",INDEX(Array_ElectricalCharges,MATCH($A8,List_ElectricityMeters,0),ROUNDUP(COLUMN()/3,0)-2)) | AQ8: =IF(ISBLANK($A8),"",INDEX(Array_ElectricalCharges,MATCH($A8,List_ElectricityMeters,0),ROUNDUP(COLUMN()/3,0)-2)) | AT8: =IF(ISBLANK($A8),"",INDEX(Array_ElectricalCharges,MATCH($A8,List_ElectricityMeters,0),ROUNDUP(COLUMN()/3,0)-2)) | AW8: =IF(ISBLANK($A8),"",INDEX(Array_ElectricalCharges,MATCH($A8,List_ElectricityMeters,0),ROUNDUP(COLUMN()/3,0)-2))
G9: =IF(ISBLANK($A9),"",INDEX(Array_ElectricalCharges,MATCH($A9,List_ElectricityMeters,0),ROUNDUP(COLUMN()/3,0)-2)) | J9: =IF(ISBLANK($A9),"",INDEX(Array_ElectricalCharges,MATCH($A9,List_ElectricityMeters,0),ROUNDUP(COLUMN()/3,0)-2)) | M9: =IF(ISBLANK($A9),"",INDEX(Array_ElectricalCharges,MATCH($A9,List_ElectricityMeters,0),ROUNDUP(COLUMN()/3,0)-2)) | P9: =IF(ISBLANK($A9),"",INDEX(Array_ElectricalCharges,MATCH($A9,List_ElectricityMeters,0),ROUNDUP(COLUMN()/3,0)-2)) | S9: =IF(ISBLANK($A9),"",INDEX(Array_ElectricalCharges,MATCH($A9,List_ElectricityMeters,0),ROUNDUP(COLUMN()/3,0)-2)) | V9: =IF(ISBLANK($A9),"",INDEX(Array_ElectricalCharges,MATCH($A9,List_ElectricityMeters,0),ROUNDUP(COLUMN()/3,0)-2)) | Y9: =IF(ISBLANK($A9),"",INDEX(Array_ElectricalCharges,MATCH($A9,List_ElectricityMeters,0),ROUNDUP(COLUMN()/3,0)-2)) | AB9: =IF(ISBLANK($A9),"",INDEX(Array_ElectricalCharges,MATCH($A9,List_ElectricityMeters,0),ROUNDUP(COLUMN()/3,0)-2)) | AE9: =IF(ISBLANK($A9),"",INDEX(Array_ElectricalCharges,MATCH($A9,List_ElectricityMeters,0),ROUNDUP(COLUMN()/3,0)-2)) | AH9: =IF(ISBLANK($A9),"",INDEX(Array_ElectricalCharges,MATCH($A9,List_ElectricityMeters,0),ROUNDUP(COLUMN()/3,0)-2)) | AK9: =IF(ISBLANK($A9),"",INDEX(Array_ElectricalCharges,MATCH($A9,List_ElectricityMeters,0),ROUNDUP(COLUMN()/3,0)-2)) | AN9: =IF(ISBLANK($A9),"",INDEX(Array_ElectricalCharges,MATCH($A9,List_ElectricityMeters,0),ROUNDUP(COLUMN()/3,0)-2)) | AQ9: =IF(ISBLANK($A9),"",INDEX(Array_ElectricalCharges,MATCH($A9,List_ElectricityMeters,0),ROUNDUP(COLUMN()/3,0)-2)) | AT9: =IF(ISBLANK($A9),"",INDEX(Array_ElectricalCharges,MATCH($A9,List_ElectricityMeters,0),ROUNDUP(COLUMN()/3,0)-2)) | AW9: =IF(ISBLANK($A9),"",INDEX(Array_ElectricalCharges,MATCH($A9,List_ElectricityMeters,0),ROUNDUP(COLUMN()/3,0)-2))
G10: =IF(ISBLANK($A10),"",INDEX(Array_ElectricalCharges,MATCH($A10,List_ElectricityMeters,0),ROUNDUP(COLUMN()/3,0)-2)) | J10: =IF(ISBLANK($A10),"",INDEX(Array_ElectricalCharges,MATCH($A10,List_ElectricityMeters,0),ROUNDUP(COLUMN()/3,0)-2)) | M10: =IF(ISBLANK($A10),"",INDEX(Array_ElectricalCharges,MATCH($A10,List_ElectricityMeters,0),ROUNDUP(COLUMN()/3,0)-2)) | P10: =IF(ISBLANK($A10),"",INDEX(Array_ElectricalCharges,MATCH($A10,List_ElectricityMeters,0),ROUNDUP(COLUMN()/3,0)-2)) | S10: =IF(ISBLANK($A10),"",INDEX(Array_ElectricalCharges,MATCH($A10,List_ElectricityMeters,0),ROUNDUP(COLUMN()/3,0)-2)) | V10: =IF(ISBLANK($A10),"",INDEX(Array_ElectricalCharges,MATCH($A10,List_ElectricityMeters,0),ROUNDUP(COLUMN()/3,0)-2)) | Y10: =IF(ISBLANK($A10),"",INDEX(Array_ElectricalCharges,MATCH($A10,List_ElectricityMeters,0),ROUNDUP(COLUMN()/3,0)-2)) | AB10: =IF(ISBLANK($A10),"",INDEX(Array_ElectricalCharges,MATCH($A10,List_ElectricityMeters,0),ROUNDUP(COLUMN()/3,0)-2)) | AE10: =IF(ISBLANK($A10),"",INDEX(Array_ElectricalCharges,MATCH($A10,List_ElectricityMeters,0),ROUNDUP(COLUMN()/3,0)-2)) | AH10: =IF(ISBLANK($A10),"",INDEX(Array_ElectricalCharges,MATCH($A10,List_ElectricityMeters,0),ROUNDUP(COLUMN()/3,0)-2)) | AK10: =IF(ISBLANK($A10),"",INDEX(Array_ElectricalCharges,MATCH($A10,List_ElectricityMeters,0),ROUNDUP(COLUMN()/3,0)-2)) | AN10: =IF(ISBLANK($A10),"",INDEX(Array_ElectricalCharges,MATCH($A10,List_ElectricityMeters,0),ROUNDUP(COLUMN()/3,0)-2)) | AQ10: =IF(ISBLANK($A10),"",INDEX(Array_ElectricalCharges,MATCH($A10,List_ElectricityMeters,0),ROUNDUP(COLUMN()/3,0)-2)) | AT10: =IF(ISBLANK($A10),"",INDEX(Array_ElectricalCharges,MATCH($A10,List_ElectricityMeters,0),ROUNDUP(COLUMN()/3,0)-2)) | AW10: =IF(ISBLANK($A10),"",INDEX(Array_ElectricalCharges,MATCH($A10,List_ElectricityMeters,0),ROUNDUP(COLUMN()/3,0)-2))
G11: =IF(ISBLANK($A11),"",INDEX(Array_ElectricalCharges,MATCH($A11,List_ElectricityMeters,0),ROUNDUP(COLUMN()/3,0)-2)) | J11: =IF(ISBLANK($A11),"",INDEX(Array_ElectricalCharges,MATCH($A11,List_ElectricityMeters,0),ROUNDUP(COLUMN()/3,0)-2)) | M11: =IF(ISBLANK($A11),"",INDEX(Array_ElectricalCharges,MATCH($A11,List_ElectricityMeters,0),ROUNDUP(COLUMN()/3,0)-2)) | P11: =IF(ISBLANK($A11),"",INDEX(Array_ElectricalCharges,MATCH($A11,List_ElectricityMeters,0),ROUNDUP(COLUMN()/3,0)-2)) | S11: =IF(ISBLANK($A11),"",INDEX(Array_ElectricalCharges,MATCH($A11,List_ElectricityMeters,0),ROUNDUP(COLUMN()/3,0)-2)) | V11: =IF(ISBLANK($A11),"",INDEX(Array_ElectricalCharges,MATCH($A11,List_ElectricityMeters,0),ROUNDUP(COLUMN()/3,0)-2)) | Y11: =IF(ISBLANK($A11),"",INDEX(Array_ElectricalCharges,MATCH($A11,List_ElectricityMeters,0),ROUNDUP(COLUMN()/3,0)-2)) | AB11: =IF(ISBLANK($A11),"",INDEX(Array_ElectricalCharges,MATCH($A11,List_ElectricityMeters,0),ROUNDUP(COLUMN()/3,0)-2)) | AE11: =IF(ISBLANK($A11),"",INDEX(Array_ElectricalCharges,MATCH($A11,List_ElectricityMeters,0),ROUNDUP(COLUMN()/3,0)-2)) | AH11: =IF(ISBLANK($A11),"",INDEX(Array_ElectricalCharges,MATCH($A11,List_ElectricityMeters,0),ROUNDUP(COLUMN()/3,0)-2)) | AK11: =IF(ISBLANK($A11),"",INDEX(Array_ElectricalCharges,MATCH($A11,List_ElectricityMeters,0),ROUNDUP(COLUMN()/3,0)-2)) | AN11: =IF(ISBLANK($A11),"",INDEX(Array_ElectricalCharges,MATCH($A11,List_ElectricityMeters,0),ROUNDUP(COLUMN()/3,0)-2)) | AQ11: =IF(ISBLANK($A11),"",INDEX(Array_ElectricalCharges,MATCH($A11,List_ElectricityMeters,0),ROUNDUP(COLUMN()/3,0)-2)) | AT11: =IF(ISBLANK($A11),"",INDEX(Array_ElectricalCharges,MATCH($A11,List_ElectricityMeters,0),ROUNDUP(COLUMN()/3,0)-2)) | AW11: =IF(ISBLANK($A11),"",INDEX(Array_ElectricalCharges,MATCH($A11,List_ElectricityMeters,0),ROUNDUP(COLUMN()/3,0)-2))
G12: =IF(ISBLANK($A12),"",INDEX(Array_ElectricalCharges,MATCH($A12,List_ElectricityMeters,0),ROUNDUP(COLUMN()/3,0)-2)) | J12: =IF(ISBLANK($A12),"",INDEX(Array_ElectricalCharges,MATCH($A12,List_ElectricityMeters,0),ROUNDUP(COLUMN()/3,0)-2)) | M12: =IF(ISBLANK($A12),"",INDEX(Array_ElectricalCharges,MATCH($A12,List_ElectricityMeters,0),ROUNDUP(COLUMN()/3,0)-2)) | P12: =IF(ISBLANK($A12),"",INDEX(Array_ElectricalCharges,MATCH($A12,List_ElectricityMeters,0),ROUNDUP(COLUMN()/3,0)-2)) | S12: =IF(ISBLANK($A12),"",INDEX(Array_ElectricalCharges,MATCH($A12,List_ElectricityMeters,0),ROUNDUP(COLUMN()/3,0)-2)) | V12: =IF(ISBLANK($A12),"",INDEX(Array_ElectricalCharges,MATCH($A12,List_ElectricityMeters,0),ROUNDUP(COLUMN()/3,0)-2)) | Y12: =IF(ISBLANK($A12),"",INDEX(Array_ElectricalCharges,MATCH($A12,List_ElectricityMeters,0),ROUNDUP(COLUMN()/3,0)-2)) | AB12: =IF(ISBLANK($A12),"",INDEX(Array_ElectricalCharges,MATCH($A12,List_ElectricityMeters,0),ROUNDUP(COLUMN()/3,0)-2)) | AE12: =IF(ISBLANK($A12),"",INDEX(Array_ElectricalCharges,MATCH($A12,List_ElectricityMeters,0),ROUNDUP(COLUMN()/3,0)-2)) | AH12: =IF(ISBLANK($A12),"",INDEX(Array_ElectricalCharges,MATCH($A12,List_ElectricityMeters,0),ROUNDUP(COLUMN()/3,0)-2)) | AK12: =IF(ISBLANK($A12),"",INDEX(Array_ElectricalCharges,MATCH($A12,List_ElectricityMeters,0),ROUNDUP(COLUMN()/3,0)-2)) | AN12: =IF(ISBLANK($A12),"",INDEX(Array_ElectricalCharges,MATCH($A12,List_ElectricityMeters,0),ROUNDUP(COLUMN()/3,0)-2)) | AQ12: =IF(ISBLANK($A12),"",INDEX(Array_ElectricalCharges,MATCH($A12,List_ElectricityMeters,0),ROUNDUP(COLUMN()/3,0)-2)) | AT12: =IF(ISBLANK($A12),"",INDEX(Array_ElectricalCharges,MATCH($A12,List_ElectricityMeters,0),ROUNDUP(COLUMN()/3,0)-2)) | AW12: =IF(ISBLANK($A12),"",INDEX(Array_ElectricalCharges,MATCH($A12,List_ElectricityMeters,0),ROUNDUP(COLUMN()/3,0)-2))
G13: =IF(ISBLANK($A13),"",INDEX(Array_ElectricalCharges,MATCH($A13,List_ElectricityMeters,0),ROUNDUP(COLUMN()/3,0)-2)) | J13: =IF(ISBLANK($A13),"",INDEX(Array_ElectricalCharges,MATCH($A13,List_ElectricityMeters,0),ROUNDUP(COLUMN()/3,0)-2)) | M13: =IF(ISBLANK($A13),"",INDEX(Array_ElectricalCharges,MATCH($A13,List_ElectricityMeters,0),ROUNDUP(COLUMN()/3,0)-2)) | P13: =IF(ISBLANK($A13),"",INDEX(Array_ElectricalCharges,MATCH($A13,List_ElectricityMeters,0),ROUNDUP(COLUMN()/3,0)-2)) | S13: =IF(ISBLANK($A13),"",INDEX(Array_ElectricalCharges,MATCH($A13,List_ElectricityMeters,0),ROUNDUP(COLUMN()/3,0)-2)) | V13: =IF(ISBLANK($A13),"",INDEX(Array_ElectricalCharges,MATCH($A13,List_ElectricityMeters,0),ROUNDUP(COLUMN()/3,0)-2)) | Y13: =IF(ISBLANK($A13),"",INDEX(Array_ElectricalCharges,MATCH($A13,List_ElectricityMeters,0),ROUNDUP(COLUMN()/3,0)-2)) | AB13: =IF(ISBLANK($A13),"",INDEX(Array_ElectricalCharges,MATCH($A13,List_ElectricityMeters,0),ROUNDUP(COLUMN()/3,0)-2)) | AE13: =IF(ISBLANK($A13),"",INDEX(Array_ElectricalCharges,MATCH($A13,List_ElectricityMeters,0),ROUNDUP(COLUMN()/3,0)-2)) | AH13: =IF(ISBLANK($A13),"",INDEX(Array_ElectricalCharges,MATCH($A13,List_ElectricityMeters,0),ROUNDUP(COLUMN()/3,0)-2)) | AK13: =IF(ISBLANK($A13),"",INDEX(Array_ElectricalCharges,MATCH($A13,List_ElectricityMeters,0),ROUNDUP(COLUMN()/3,0)-2)) | AN13: =IF(ISBLANK($A13),"",INDEX(Array_ElectricalCharges,MATCH($A13,List_ElectricityMeters,0),ROUNDUP(COLUMN()/3,0)-2)) | AQ13: =IF(ISBLANK($A13),"",INDEX(Array_ElectricalCharges,MATCH($A13,List_ElectricityMeters,0),ROUNDUP(COLUMN()/3,0)-2)) | AT13: =IF(ISBLANK($A13),"",INDEX(Array_ElectricalCharges,MATCH($A13,List_ElectricityMeters,0),ROUNDUP(COLUMN()/3,0)-2)) | AW13: =IF(ISBLANK($A13),"",INDEX(Array_ElectricalCharges,MATCH($A13,List_ElectricityMeters,0),ROUNDUP(COLUMN()/3,0)-2))
G14: =IF(ISBLANK($A14),"",INDEX(Array_ElectricalCharges,MATCH($A14,List_ElectricityMeters,0),ROUNDUP(COLUMN()/3,0)-2)) | J14: =IF(ISBLANK($A14),"",INDEX(Array_ElectricalCharges,MATCH($A14,List_ElectricityMeters,0),ROUNDUP(COLUMN()/3,0)-2)) | M14: =IF(ISBLANK($A14),"",INDEX(Array_ElectricalCharges,MATCH($A14,List_ElectricityMeters,0),ROUNDUP(COLUMN()/3,0)-2)) | P14: =IF(ISBLANK($A14),"",INDEX(Array_ElectricalCharges,MATCH($A14,List_ElectricityMeters,0),ROUNDUP(COLUMN()/3,0)-2)) | S14: =IF(ISBLANK($A14),"",INDEX(Array_ElectricalCharges,MATCH($A14,List_ElectricityMeters,0),ROUNDUP(COLUMN()/3,0)-2)) | V14: =IF(ISBLANK($A14),"",INDEX(Array_ElectricalCharges,MATCH($A14,List_ElectricityMeters,0),ROUNDUP(COLUMN()/3,0)-2)) | Y14: =IF(ISBLANK($A14),"",INDEX(Array_ElectricalCharges,MATCH($A14,List_ElectricityMeters,0),ROUNDUP(COLUMN()/3,0)-2)) | AB14: =IF(ISBLANK($A14),"",INDEX(Array_ElectricalCharges,MATCH($A14,List_ElectricityMeters,0),ROUNDUP(COLUMN()/3,0)-2)) | AE14: =IF(ISBLANK($A14),"",INDEX(Array_ElectricalCharges,MATCH($A14,List_ElectricityMeters,0),ROUNDUP(COLUMN()/3,0)-2)) | AH14: =IF(ISBLANK($A14),"",INDEX(Array_ElectricalCharges,MATCH($A14,List_ElectricityMeters,0),ROUNDUP(COLUMN()/3,0)-2)) | AK14: =IF(ISBLANK($A14),"",INDEX(Array_ElectricalCharges,MATCH($A14,List_ElectricityMeters,0),ROUNDUP(COLUMN()/3,0)-2)) | AN14: =IF(ISBLANK($A14),"",INDEX(Array_ElectricalCharges,MATCH($A14,List_ElectricityMeters,0),ROUNDUP(COLUMN()/3,0)-2)) | AQ14: =IF(ISBLANK($A14),"",INDEX(Array_ElectricalCharges,MATCH($A14,List_ElectricityMeters,0),ROUNDUP(COLUMN()/3,0)-2)) | AT14: =IF(ISBLANK($A14),"",INDEX(Array_ElectricalCharges,MATCH($A14,List_ElectricityMeters,0),ROUNDUP(COLUMN()/3,0)-2)) | AW14: =IF(ISBLANK($A14),"",INDEX(Array_ElectricalCharges,MATCH($A14,List_ElectricityMeters,0),ROUNDUP(COLUMN()/3,0)-2))
... G502: =IF(ISBLANK($A502),"",INDEX(Array_ElectricalCharges,MATCH($A502,List_ElectricityMeters,0),ROUNDUP(COLUMN()/3,0)-2)) | J502: =IF(ISBLANK($A502),"",INDEX(Array_ElectricalCharges,MATCH($A502,List_ElectricityMeters,0),ROUNDUP(COLUMN()/3,0)-2)) | M502: =IF(ISBLANK($A502),"",INDEX(Array_ElectricalCharges,MATCH($A502,List_ElectricityMeters,0),ROUNDUP(COLUMN()/3,0)-2)) | P502: =IF(ISBLANK($A502),"",INDEX(Array_ElectricalCharges,MATCH($A502,List_ElectricityMeters,0),ROUNDUP(COLUMN()/3,0)-2)) | S502: =IF(ISBLANK($A502),"",INDEX(Array_ElectricalCharges,MATCH($A502,List_ElectricityMeters,0),ROUNDUP(COLUMN()/3,0)-2)) | V502: =IF(ISBLANK($A502),"",INDEX(Array_ElectricalCharges,MATCH($A502,List_ElectricityMeters,0),ROUNDUP(COLUMN()/3,0)-2)) | Y502: =IF(ISBLANK($A502),"",INDEX(Array_ElectricalCharges,MATCH($A502,List_ElectricityMeters,0),ROUNDUP(COLUMN()/3,0)-2)) | AB502: =IF(ISBLANK($A502),"",INDEX(Array_ElectricalCharges,MATCH($A502,List_ElectricityMeters,0),ROUNDUP(COLUMN()/3,0)-2)) | AE502: =IF(ISBLANK($A502),"",INDEX(Array_ElectricalCharges,MATCH($A502,List_ElectricityMeters,0),ROUNDUP(COLUMN()/3,0)-2)) | AH502: =IF(ISBLANK($A502),"",INDEX(Array_ElectricalCharges,MATCH($A502,List_ElectricityMeters,0),ROUNDUP(COLUMN()/3,0)-2)) | AK502: =IF(ISBLANK($A502),"",INDEX(Array_ElectricalCharges,MATCH($A502,List_ElectricityMeters,0),ROUNDUP(COLUMN()/3,0)-2)) | AN502: =IF(ISBLANK($A502),"",INDEX(Array_ElectricalCharges,MATCH($A502,List_ElectricityMeters,0),ROUNDUP(COLUMN()/3,0)-2)) | AQ502: =IF(ISBLANK($A502),"",INDEX(Array_ElectricalCharges,MATCH($A502,List_ElectricityMeters,0),ROUNDUP(COLUMN()/3,0)-2)) | AT502: =IF(ISBLANK($A502),"",INDEX(Array_ElectricalCharges,MATCH($A502,List_ElectricityMeters,0),ROUNDUP(COLUMN()/3,0)-2)) | AW502: =IF(ISBLANK($A502),"",INDEX(Array_ElectricalCharges,MATCH($A502,List_ElectricityMeters,0),ROUNDUP(COLUMN()/3,0)-2))

Sheet HIDE_ELEC
A1: Agreement Type | B1: Calendarize Options | C1: Usage Units | D1: Demand Units | E1: Charge Types | J1: Other Settings | K1: Value
A2: Grid Electricity | B2: Yes | C2: kWh | D2: kW | E2: Consumption | J2: Source | K2: Electricity
A3: Other Non-RE Electricity | B3: No | C3: MWh | D3: kVA | E3: Demand | J3: Scope | K3: Scope 2: Purchased Electricity
A4: Utility Green Product | B4: Evenly Distribute | C4: MMBtu | D4: MW | E4: Tax | J4: Max Allowed Charges | K4: 16
A5: Onsite Renewable Energy | C5: GJ | D5: MVA | E5: Late Fee
A6: Direct Delivered Physical Power Purchase Agreement (P-PPA) | C6: MJ | E6: Flat Fee
A7: Grid Delivered Physical Power Purchase Agreement (P-PPA) | C7: kJ | E7: Other | J7: REACTIVE TABLE
A8: Virtual Power Purchase Agreement | C8: Therms
A9: Unbundled RECs | C9: DTherms | J9: FIXED LIST
C10: kcal
A15: Charge count: | B15: =COUNTIF(B17:B116,"?*") -> 0 | C15: =COUNTIF(C17:C116,"?*") -> 0 | D15: =COUNTIF(D17:D116,"?*") -> 0 | E15: =COUNTIF(E17:E116,"?*") -> 0 | F15: =COUNTIF(F17:F116,"?*") -> 0 | G15: =COUNTIF(G17:G116,"?*") -> 0 | H15: =COUNTIF(H17:H116,"?*") -> 0 | I15: =COUNTIF(I17:I116,"?*") -> 0 | ... P15: =COUNTIF(P17:P116,"?*") -> 0
A16: Meter Numbers | B16: Charge 1 | C16: Charge 2 | D16: Charge 3 | E16: Charge 4 | F16: Charge 5 | G16: Charge 6 | H16: Charge 7 | I16: Charge 8 | J16: Charge 9 | K16: Charge 10 | L16: Charge 11 | M16: Charge 12 | N16: Charge 13 | O16: Charge 14 | P16: Charge 15
A17: =IF('Electricity Meters'!B3="",A16,'Electricity Meters'!B3) -> Meter Numbers | B17: =IF(ISBLANK(INDEX(Array_ElectricalChargeData,ROW()-16,COLUMN()*2-3)),"",INDEX(Array_ElectricalChargeData,ROW()-16,COLUMN()*2-3)) | C17: =IF(ISBLANK(INDEX(Array_ElectricalChargeData,ROW()-16,COLUMN()*2-3)),"",INDEX(Array_ElectricalChargeData,ROW()-16,COLUMN()*2-3)) | D17: =IF(ISBLANK(INDEX(Array_ElectricalChargeData,ROW()-16,COLUMN()*2-3)),"",INDEX(Array_ElectricalChargeData,ROW()-16,COLUMN()*2-3)) | E17: =IF(ISBLANK(INDEX(Array_ElectricalChargeData,ROW()-16,COLUMN()*2-3)),"",INDEX(Array_ElectricalChargeData,ROW()-16,COLUMN()*2-3)) | F17: =IF(ISBLANK(INDEX(Array_ElectricalChargeData,ROW()-16,COLUMN()*2-3)),"",INDEX(Array_ElectricalChargeData,ROW()-16,COLUMN()*2-3)) | G17: =IF(ISBLANK(INDEX(Array_ElectricalChargeData,ROW()-16,COLUMN()*2-3)),"",INDEX(Array_ElectricalChargeData,ROW()-16,COLUMN()*2-3)) | H17: =IF(ISBLANK(INDEX(Array_ElectricalChargeData,ROW()-16,COLUMN()*2-3)),"",INDEX(Array_ElectricalChargeData,ROW()-16,COLUMN()*2-3)) | I17: =IF(ISBLANK(INDEX(Array_ElectricalChargeData,ROW()-16,COLUMN()*2-3)),"",INDEX(Array_ElectricalChargeData,ROW()-16,COLUMN()*2-3)) | ... P17: =IF(ISBLANK(INDEX(Array_ElectricalChargeData,ROW()-16,COLUMN()*2-3)),"",INDEX(Array_ElectricalChargeData,ROW()-16,COLUMN()*2-3))
A18: =IF('Electricity Meters'!B4="",A17,'Electricity Meters'!B4) -> Meter Numbers | B18: =IF(ISBLANK(INDEX(Array_ElectricalChargeData,ROW()-16,COLUMN()*2-3)),"",INDEX(Array_ElectricalChargeData,ROW()-16,COLUMN()*2-3)) | C18: =IF(ISBLANK(INDEX(Array_ElectricalChargeData,ROW()-16,COLUMN()*2-3)),"",INDEX(Array_ElectricalChargeData,ROW()-16,COLUMN()*2-3)) | D18: =IF(ISBLANK(INDEX(Array_ElectricalChargeData,ROW()-16,COLUMN()*2-3)),"",INDEX(Array_ElectricalChargeData,ROW()-16,COLUMN()*2-3)) | E18: =IF(ISBLANK(INDEX(Array_ElectricalChargeData,ROW()-16,COLUMN()*2-3)),"",INDEX(Array_ElectricalChargeData,ROW()-16,COLUMN()*2-3)) | F18: =IF(ISBLANK(INDEX(Array_ElectricalChargeData,ROW()-16,COLUMN()*2-3)),"",INDEX(Array_ElectricalChargeData,ROW()-16,COLUMN()*2-3)) | G18: =IF(ISBLANK(INDEX(Array_ElectricalChargeData,ROW()-16,COLUMN()*2-3)),"",INDEX(Array_ElectricalChargeData,ROW()-16,COLUMN()*2-3)) | H18: =IF(ISBLANK(INDEX(Array_ElectricalChargeData,ROW()-16,COLUMN()*2-3)),"",INDEX(Array_ElectricalChargeData,ROW()-16,COLUMN()*2-3)) | I18: =IF(ISBLANK(INDEX(Array_ElectricalChargeData,ROW()-16,COLUMN()*2-3)),"",INDEX(Array_ElectricalChargeData,ROW()-16,COLUMN()*2-3)) | ... P18: =IF(ISBLANK(INDEX(Array_ElectricalChargeData,ROW()-16,COLUMN()*2-3)),"",INDEX(Array_ElectricalChargeData,ROW()-16,COLUMN()*2-3))
A19: =IF('Electricity Meters'!B5="",A18,'Electricity Meters'!B5) -> Meter Numbers | B19: =IF(ISBLANK(INDEX(Array_ElectricalChargeData,ROW()-16,COLUMN()*2-3)),"",INDEX(Array_ElectricalChargeData,ROW()-16,COLUMN()*2-3)) | C19: =IF(ISBLANK(INDEX(Array_ElectricalChargeData,ROW()-16,COLUMN()*2-3)),"",INDEX(Array_ElectricalChargeData,ROW()-16,COLUMN()*2-3)) | D19: =IF(ISBLANK(INDEX(Array_ElectricalChargeData,ROW()-16,COLUMN()*2-3)),"",INDEX(Array_ElectricalChargeData,ROW()-16,COLUMN()*2-3)) | E19: =IF(ISBLANK(INDEX(Array_ElectricalChargeData,ROW()-16,COLUMN()*2-3)),"",INDEX(Array_ElectricalChargeData,ROW()-16,COLUMN()*2-3)) | F19: =IF(ISBLANK(INDEX(Array_ElectricalChargeData,ROW()-16,COLUMN()*2-3)),"",INDEX(Array_ElectricalChargeData,ROW()-16,COLUMN()*2-3)) | G19: =IF(ISBLANK(INDEX(Array_ElectricalChargeData,ROW()-16,COLUMN()*2-3)),"",INDEX(Array_ElectricalChargeData,ROW()-16,COLUMN()*2-3)) | H19: =IF(ISBLANK(INDEX(Array_ElectricalChargeData,ROW()-16,COLUMN()*2-3)),"",INDEX(Array_ElectricalChargeData,ROW()-16,COLUMN()*2-3)) | I19: =IF(ISBLANK(INDEX(Array_ElectricalChargeData,ROW()-16,COLUMN()*2-3)),"",INDEX(Array_ElectricalChargeData,ROW()-16,COLUMN()*2-3)) | ... P19: =IF(ISBLANK(INDEX(Array_ElectricalChargeData,ROW()-16,COLUMN()*2-3)),"",INDEX(Array_ElectricalChargeData,ROW()-16,COLUMN()*2-3))
A20: =IF('Electricity Meters'!B6="",A19,'Electricity Meters'!B6) -> Meter Numbers | B20: =IF(ISBLANK(INDEX(Array_ElectricalChargeData,ROW()-16,COLUMN()*2-3)),"",INDEX(Array_ElectricalChargeData,ROW()-16,COLUMN()*2-3)) | C20: =IF(ISBLANK(INDEX(Array_ElectricalChargeData,ROW()-16,COLUMN()*2-3)),"",INDEX(Array_ElectricalChargeData,ROW()-16,COLUMN()*2-3)) | D20: =IF(ISBLANK(INDEX(Array_ElectricalChargeData,ROW()-16,COLUMN()*2-3)),"",INDEX(Array_ElectricalChargeData,ROW()-16,COLUMN()*2-3)) | E20: =IF(ISBLANK(INDEX(Array_ElectricalChargeData,ROW()-16,COLUMN()*2-3)),"",INDEX(Array_ElectricalChargeData,ROW()-16,COLUMN()*2-3)) | F20: =IF(ISBLANK(INDEX(Array_ElectricalChargeData,ROW()-16,COLUMN()*2-3)),"",INDEX(Array_ElectricalChargeData,ROW()-16,COLUMN()*2-3)) | G20: =IF(ISBLANK(INDEX(Array_ElectricalChargeData,ROW()-16,COLUMN()*2-3)),"",INDEX(Array_ElectricalChargeData,ROW()-16,COLUMN()*2-3)) | H20: =IF(ISBLANK(INDEX(Array_ElectricalChargeData,ROW()-16,COLUMN()*2-3)),"",INDEX(Array_ElectricalChargeData,ROW()-16,COLUMN()*2-3)) | I20: =IF(ISBLANK(INDEX(Array_ElectricalChargeData,ROW()-16,COLUMN()*2-3)),"",INDEX(Array_ElectricalChargeData,ROW()-16,COLUMN()*2-3)) | ... P20: =IF(ISBLANK(INDEX(Array_ElectricalChargeData,ROW()-16,COLUMN()*2-3)),"",INDEX(Array_ElectricalChargeData,ROW()-16,COLUMN()*2-3))
A21: =IF('Electricity Meters'!B7="",A20,'Electricity Meters'!B7) -> Meter Numbers | B21: =IF(ISBLANK(INDEX(Array_ElectricalChargeData,ROW()-16,COLUMN()*2-3)),"",INDEX(Array_ElectricalChargeData,ROW()-16,COLUMN()*2-3)) | C21: =IF(ISBLANK(INDEX(Array_ElectricalChargeData,ROW()-16,COLUMN()*2-3)),"",INDEX(Array_ElectricalChargeData,ROW()-16,COLUMN()*2-3)) | D21: =IF(ISBLANK(INDEX(Array_ElectricalChargeData,ROW()-16,COLUMN()*2-3)),"",INDEX(Array_ElectricalChargeData,ROW()-16,COLUMN()*2-3)) | E21: =IF(ISBLANK(INDEX(Array_ElectricalChargeData,ROW()-16,COLUMN()*2-3)),"",INDEX(Array_ElectricalChargeData,ROW()-16,COLUMN()*2-3)) | F21: =IF(ISBLANK(INDEX(Array_ElectricalChargeData,ROW()-16,COLUMN()*2-3)),"",INDEX(Array_ElectricalChargeData,ROW()-16,COLUMN()*2-3)) | G21: =IF(ISBLANK(INDEX(Array_ElectricalChargeData,ROW()-16,COLUMN()*2-3)),"",INDEX(Array_ElectricalChargeData,ROW()-16,COLUMN()*2-3)) | H21: =IF(ISBLANK(INDEX(Array_ElectricalChargeData,ROW()-16,COLUMN()*2-3)),"",INDEX(Array_ElectricalChargeData,ROW()-16,COLUMN()*2-3)) | I21: =IF(ISBLANK(INDEX(Array_ElectricalChargeData,ROW()-16,COLUMN()*2-3)),"",INDEX(Array_ElectricalChargeData,ROW()-16,COLUMN()*2-3)) | ... P21: =IF(ISBLANK(INDEX(Array_ElectricalChargeData,ROW()-16,COLUMN()*2-3)),"",INDEX(Array_ElectricalChargeData,ROW()-16,COLUMN()*2-3))
A22: =IF('Electricity Meters'!B8="",A21,'Electricity Meters'!B8) -> Meter Numbers | B22: =IF(ISBLANK(INDEX(Array_ElectricalChargeData,ROW()-16,COLUMN()*2-3)),"",INDEX(Array_ElectricalChargeData,ROW()-16,COLUMN()*2-3)) | C22: =IF(ISBLANK(INDEX(Array_ElectricalChargeData,ROW()-16,COLUMN()*2-3)),"",INDEX(Array_ElectricalChargeData,ROW()-16,COLUMN()*2-3)) | D22: =IF(ISBLANK(INDEX(Array_ElectricalChargeData,ROW()-16,COLUMN()*2-3)),"",INDEX(Array_ElectricalChargeData,ROW()-16,COLUMN()*2-3)) | E22: =IF(ISBLANK(INDEX(Array_ElectricalChargeData,ROW()-16,COLUMN()*2-3)),"",INDEX(Array_ElectricalChargeData,ROW()-16,COLUMN()*2-3)) | F22: =IF(ISBLANK(INDEX(Array_ElectricalChargeData,ROW()-16,COLUMN()*2-3)),"",INDEX(Array_ElectricalChargeData,ROW()-16,COLUMN()*2-3)) | G22: =IF(ISBLANK(INDEX(Array_ElectricalChargeData,ROW()-16,COLUMN()*2-3)),"",INDEX(Array_ElectricalChargeData,ROW()-16,COLUMN()*2-3)) | H22: =IF(ISBLANK(INDEX(Array_ElectricalChargeData,ROW()-16,COLUMN()*2-3)),"",INDEX(Array_ElectricalChargeData,ROW()-16,COLUMN()*2-3)) | I22: =IF(ISBLANK(INDEX(Array_ElectricalChargeData,ROW()-16,COLUMN()*2-3)),"",INDEX(Array_ElectricalChargeData,ROW()-16,COLUMN()*2-3)) | ... P22: =IF(ISBLANK(INDEX(Array_ElectricalChargeData,ROW()-16,COLUMN()*2-3)),"",INDEX(Array_ElectricalChargeData,ROW()-16,COLUMN()*2-3))
A23: =IF('Electricity Meters'!B9="",A22,'Electricity Meters'!B9) -> Meter Numbers | B23: =IF(ISBLANK(INDEX(Array_ElectricalChargeData,ROW()-16,COLUMN()*2-3)),"",INDEX(Array_ElectricalChargeData,ROW()-16,COLUMN()*2-3)) | C23: =IF(ISBLANK(INDEX(Array_ElectricalChargeData,ROW()-16,COLUMN()*2-3)),"",INDEX(Array_ElectricalChargeData,ROW()-16,COLUMN()*2-3)) | D23: =IF(ISBLANK(INDEX(Array_ElectricalChargeData,ROW()-16,COLUMN()*2-3)),"",INDEX(Array_ElectricalChargeData,ROW()-16,COLUMN()*2-3)) | E23: =IF(ISBLANK(INDEX(Array_ElectricalChargeData,ROW()-16,COLUMN()*2-3)),"",INDEX(Array_ElectricalChargeData,ROW()-16,COLUMN()*2-3)) | F23: =IF(ISBLANK(INDEX(Array_ElectricalChargeData,ROW()-16,COLUMN()*2-3)),"",INDEX(Array_ElectricalChargeData,ROW()-16,COLUMN()*2-3)) | G23: =IF(ISBLANK(INDEX(Array_ElectricalChargeData,ROW()-16,COLUMN()*2-3)),"",INDEX(Array_ElectricalChargeData,ROW()-16,COLUMN()*2-3)) | H23: =IF(ISBLANK(INDEX(Array_ElectricalChargeData,ROW()-16,COLUMN()*2-3)),"",INDEX(Array_ElectricalChargeData,ROW()-16,COLUMN()*2-3)) | I23: =IF(ISBLANK(INDEX(Array_ElectricalChargeData,ROW()-16,COLUMN()*2-3)),"",INDEX(Array_ElectricalChargeData,ROW()-16,COLUMN()*2-3)) | ... P23: =IF(ISBLANK(INDEX(Array_ElectricalChargeData,ROW()-16,COLUMN()*2-3)),"",INDEX(Array_ElectricalChargeData,ROW()-16,COLUMN()*2-3))
A24: =IF('Electricity Meters'!B10="",A23,'Electricity Meters'!B10) -> Meter Numbers | B24: =IF(ISBLANK(INDEX(Array_ElectricalChargeData,ROW()-16,COLUMN()*2-3)),"",INDEX(Array_ElectricalChargeData,ROW()-16,COLUMN()*2-3)) | C24: =IF(ISBLANK(INDEX(Array_ElectricalChargeData,ROW()-16,COLUMN()*2-3)),"",INDEX(Array_ElectricalChargeData,ROW()-16,COLUMN()*2-3)) | D24: =IF(ISBLANK(INDEX(Array_ElectricalChargeData,ROW()-16,COLUMN()*2-3)),"",INDEX(Array_ElectricalChargeData,ROW()-16,COLUMN()*2-3)) | E24: =IF(ISBLANK(INDEX(Array_ElectricalChargeData,ROW()-16,COLUMN()*2-3)),"",INDEX(Array_ElectricalChargeData,ROW()-16,COLUMN()*2-3)) | F24: =IF(ISBLANK(INDEX(Array_ElectricalChargeData,ROW()-16,COLUMN()*2-3)),"",INDEX(Array_ElectricalChargeData,ROW()-16,COLUMN()*2-3)) | G24: =IF(ISBLANK(INDEX(Array_ElectricalChargeData,ROW()-16,COLUMN()*2-3)),"",INDEX(Array_ElectricalChargeData,ROW()-16,COLUMN()*2-3)) | H24: =IF(ISBLANK(INDEX(Array_ElectricalChargeData,ROW()-16,COLUMN()*2-3)),"",INDEX(Array_ElectricalChargeData,ROW()-16,COLUMN()*2-3)) | I24: =IF(ISBLANK(INDEX(Array_ElectricalChargeData,ROW()-16,COLUMN()*2-3)),"",INDEX(Array_ElectricalChargeData,ROW()-16,COLUMN()*2-3)) | ... P24: =IF(ISBLANK(INDEX(Array_ElectricalChargeData,ROW()-16,COLUMN()*2-3)),"",INDEX(Array_ElectricalChargeData,ROW()-16,COLUMN()*2-3))
A25: =IF('Electricity Meters'!B11="",A24,'Electricity Meters'!B11) -> Meter Numbers | B25: =IF(ISBLANK(INDEX(Array_ElectricalChargeData,ROW()-16,COLUMN()*2-3)),"",INDEX(Array_ElectricalChargeData,ROW()-16,COLUMN()*2-3)) | C25: =IF(ISBLANK(INDEX(Array_ElectricalChargeData,ROW()-16,COLUMN()*2-3)),"",INDEX(Array_ElectricalChargeData,ROW()-16,COLUMN()*2-3)) | D25: =IF(ISBLANK(INDEX(Array_ElectricalChargeData,ROW()-16,COLUMN()*2-3)),"",INDEX(Array_ElectricalChargeData,ROW()-16,COLUMN()*2-3)) | E25: =IF(ISBLANK(INDEX(Array_ElectricalChargeData,ROW()-16,COLUMN()*2-3)),"",INDEX(Array_ElectricalChargeData,ROW()-16,COLUMN()*2-3)) | F25: =IF(ISBLANK(INDEX(Array_ElectricalChargeData,ROW()-16,COLUMN()*2-3)),"",INDEX(Array_ElectricalChargeData,ROW()-16,COLUMN()*2-3)) | G25: =IF(ISBLANK(INDEX(Array_ElectricalChargeData,ROW()-16,COLUMN()*2-3)),"",INDEX(Array_ElectricalChargeData,ROW()-16,COLUMN()*2-3)) | H25: =IF(ISBLANK(INDEX(Array_ElectricalChargeData,ROW()-16,COLUMN()*2-3)),"",INDEX(Array_ElectricalChargeData,ROW()-16,COLUMN()*2-3)) | I25: =IF(ISBLANK(INDEX(Array_ElectricalChargeData,ROW()-16,COLUMN()*2-3)),"",INDEX(Array_ElectricalChargeData,ROW()-16,COLUMN()*2-3)) | ... P25: =IF(ISBLANK(INDEX(Array_ElectricalChargeData,ROW()-16,COLUMN()*2-3)),"",INDEX(Array_ElectricalChargeData,ROW()-16,COLUMN()*2-3))
